Workbook

Sheet ESTADOS FINANCIEROS
B3: ESTADOS FINANCIEROS REVISORIA
B5: CUENTA | C5: Fecha corte año anterior | D5: Fecha corte año anterior | E5: Fecha corte año anterior | F5: AJUSTES / RECLASIFICACIONES | H5: Fecha corte año actual
A6: =CONCATENATE("Código","+",B6) -> Código+Activo | B6: Activo | C6: Al 01/12/2025 | D6: Al 31/07/2023 | E6: Al 31/12/2022 | F6: Debe | G6: Haber | H6: Al 31/12/2024
A7: 1 | B7: Efectivo y Equivalentes | C7: 100000 | D7: 50000000 | E7: 10000000 | F7: 150000000 | G7: 120000000 | H7: 750000000
A8: 2 | B8: Inversiones | C8: 15000 | D8: 370000 | E8: 850000 | F8: 15000 | G8: 121000 | H8: 15000000
A9: 3 | B9: Cuentas por Cobrar | C9: 15000 | D9: 370000 | E9: 850000 | F9: 15000 | G9: 121000 | H9: 15000000
A10: 4 | B10: Inventarios | C10: 15000 | D10: 370000 | E10: 850000 | F10: 15000 | G10: 121000 | H10: 15000000
A11: 5 | B11: Propiedad, Planta y Equipo | C11: 15000 | D11: 370000 | E11: 850000 | F11: 15000 | G11: 121000 | H11: 15000000
A12: 6 | B12: Ejemplo XXXXX | C12: 100000 | D12: 50000000 | E12: 10000000 | F12: 150000000 | G12: 120000000 | H12: 750000000
A13: 7 | B13: Casa | C13: 100000 | D13: 50000000 | E13: 10000000 | F13: 150000000 | G13: 120000000 | H13: 750000000
A14: 8 | B14: PRUEBA2 | C14: 1 | D14: 1 | E14: 1 | F14: 1 | G14: 1 | H14: 1
A15: 9 | B15: PRIEBA3 | C15: 1 | D15: 1 | E15: 1 | F15: 1 | G15: 1 | H15: 1
A16: 10
A17: 11
A18: 12
A19: 13
A20: 14
A21: 15
A22: 16
A23: 17
A24: 18
A25: 19
A26: 20
B27: TOTAL ACTIVO | C27: =SUM(C7:C12) -> 260000 | D27: =SUM(D7:D12) -> 101480000 | E27: =SUM(E7:E12) -> 23400000 | F27: =SUM(F7:F12) -> 300060000 | G27: =SUM(G7:G12) -> 240484000 | H27: =SUM(H7:H12) -> 1560000000
A28: =CONCATENATE("Código","+",B28) -> Código+Pasivo | B28: Pasivo
A29: 1 | B29: Pasivos | C29: 15000 | D29: 370000 | E29: 850000 | F29: 15000 | G29: 121000 | H29: 15000000
A30: 2 | B30: Pasivos2 | C30: 16000 | D30: 370000 | E30: 850000 | F30: 15000 | G30: 121000 | H30: 15000000
A31: 3 | B31: Pasivos3 | C31: 17000 | D31: 370000 | E31: 850000 | F31: 15000 | G31: 121000 | H31: 15000000
A32: 4
A33: 5
A34: 6
A35: 7
A36: 8
A37: 9
A38: 10
A39: 11
A40: 12
A41: 13
A42: 14
A43: 15
...

Sheet SUBCUENTAS ACTIVO 
A3: SUBCUENTAS - DETALLE ESTADOS FINANCIEROS
A5: SUBCUENTA | B5: Fecha corte año anterior | C5: Fecha corte año anterior | D5: Fecha corte año anterior | E5: AJUSTES / RECLASIFICACIONES | G5: Fecha corte año actual
A6: Descripción | B6: Al 01/01/2023 | C6: Al 31/07/2023 | D6: Al 31/12/2023 | E6: Debe | F6: Haber | G6: Al 31/12/2024
A7: ACTIVO
A8: Efectivo y Equivalentes | B8: 100000 | C8: ='ESTADOS FINANCIEROS'!D7 -> 50000000 | D8: ='ESTADOS FINANCIEROS'!E7 -> 10000000 | E8: ='ESTADOS FINANCIEROS'!F7 -> 150000000 | F8: ='ESTADOS FINANCIEROS'!G7 -> 120000000 | G8: ='ESTADOS FINANCIEROS'!H7 -> 750000000
A9: Caja General | B9: 50000 | C9: 25000000 | D9: 2500000 | E9: 50000000 | F9: 100000000 | G9: 500000000 | I9: Nota aquí que el excel funcione para aumentar mas subcuentas en cada cuenta
A10: Bancos Moneda Nacional | B10: 25000 | C10: 15000000 | D10: 2500000 | E10: 50000000 | F10: 10000000 | G10: 200000000
A11: Bancos Moneda Extranjera | B11: 25000 | C11: 10000000 | D11: 5000000 | E11: 50000000 | F11: 10000000 | G11: 50000000 | I11: igual en Cedulsa Sumarias seria lo mismo que cuando aumente automaticamente el excel del sistema aumente o disminuya
A12: abc | B12: 1 | C12: 1 | D12: 1 | E12: 1 | F12: 1 | G12: 1
A13: ert | B13: 2 | C13: 3 | D13: 4 | E13: 56 | F13: 7 | G13: 8
A14: yui | B14: 5 | C14: 4 | D14: 3 | E14: 2 | F14: 1 | G14: 1
A15: trt | B15: 1 | C15: 2 | D15: 3 | E15: 4 | F15: 5 | G15: 6
A16: gft | B16: 1 | C16: 1 | D16: 1 | E16: 1 | F16: 1 | G16: 1
A26: Total Efectivo y Equivalentes | B26: =SUM(B9:B11) -> 100000 | C26: =SUM(C9:C16) -> 50000011 | D26: =SUM(D9:D16) -> 10000012 | E26: =SUM(E9:E16) -> 150000064 | F26: =SUM(F9:F16) -> 120000015 | G26: =SUM(G9:G13) -> 750000009 | I26: según necesidad de la persona
A28: Inversiones | B28: ='ESTADOS FINANCIEROS'!C8 -> 15000 | C28: ='ESTADOS FINANCIEROS'!D8 -> 370000 | D28: ='ESTADOS FINANCIEROS'!E8 -> 850000 | E28: ='ESTADOS FINANCIEROS'!F8 -> 15000 | F28: ='ESTADOS FINANCIEROS'!G8 -> 121000 | G28: ='ESTADOS FINANCIEROS'!H8 -> 15000000
A29: Inversiones Temporales
A30: Inversiones Permanentes
A31: Inversiones en Bonos
A40: Total Inversiones | B40: =SUM(B29:B39) -> 0 | C40: =SUM(C29:C39) -> 0 | D40: =SUM(D29:D39) -> 0 | E40: =SUM(E29:E39) -> 0 | F40: =SUM(F29:F39) -> 0 | G40: =SUM(G29:G39) -> 0
A42: Cuentas por Cobrar | B42: ='ESTADOS FINANCIEROS'!C9 -> 15000 | C42: ='ESTADOS FINANCIEROS'!D9 -> 370000 | D42: ='ESTADOS FINANCIEROS'!E9 -> 850000 | E42: ='ESTADOS FINANCIEROS'!F9 -> 15000 | F42: ='ESTADOS FINANCIEROS'!G9 -> 121000 | G42: ='ESTADOS FINANCIEROS'!H9 -> 15000000
A43: Clientes Nacionales
A44: Clientes Extranjeros
A45: Deudores Varios
A46: Provisión Cartera (-)
A71: Total Cuentas por Cobrar | B71: =SUM(B43:B70) -> 0 | C71: =SUM(C43:C70) -> 0 | D71: =SUM(D43:D70) -> 0 | E71: =SUM(E43:E70) -> 0 | F71: =SUM(F43:F70) -> 0 | G71: =SUM(G43:G70) -> 0
A73: Inventarios | B73: ='ESTADOS FINANCIEROS'!C10 -> 15000 | C73: ='ESTADOS FINANCIEROS'!D10 -> 370000 | D73: ='ESTADOS FINANCIEROS'!E10 -> 850000 | E73: ='ESTADOS FINANCIEROS'!F10 -> 15000 | F73: ='ESTADOS FINANCIEROS'!G10 -> 121000 | G73: ='ESTADOS FINANCIEROS'!H10 -> 15000000
A74: Mercancías
A75: Productos Terminados
A90: Materia Prima
A91: Total Inventarios | B91: =SUM(B74:B90) -> 0 | C91: =SUM(C74:C90) -> 0 | D91: =SUM(D74:D90) -> 0 | E91: =SUM(E74:E90) -> 0 | F91: =SUM(F74:F90) -> 0 | G91: =SUM(G74:G90) -> 0
A93: Propiedad, Planta y Equipo | B93: ='ESTADOS FINANCIEROS'!C11 -> 15000 | C93: ='ESTADOS FINANCIEROS'!D11 -> 370000 | D93: ='ESTADOS FINANCIEROS'!E11 -> 850000 | E93: ='ESTADOS FINANCIEROS'!F11 -> 15000 | F93: ='ESTADOS FINANCIEROS'!G11 -> 121000 | G93: ='ESTADOS FINANCIEROS'!H11 -> 15000000
A94: Terrenos
A95: Edificios
A96: Maquinaria y Equipo
A97: Muebles y Enseres
A109: Depreciación Acumulada (-)
A110: Propiedad, Planta y Equipo | B110: ='ESTADOS FINANCIEROS'!C28 -> 0 | C110: ='ESTADOS FINANCIEROS'!D28 -> 0 | D110: ='ESTADOS FINANCIEROS'!E28 -> 0 | E110: ='ESTADOS FINANCIEROS'!F28 -> 0 | F110: ='ESTADOS FINANCIEROS'!G28 -> 0 | G110: ='ESTADOS FINANCIEROS'!H28 -> 0
A112: Casa | B112: ='ESTADOS FINANCIEROS'!C30 -> 16000 | C112: ='ESTADOS FINANCIEROS'!D30 -> 370000 | D112: ='ESTADOS FINANCIEROS'!E30 -> 850000 | E112: ='ESTADOS FINANCIEROS'!F30 -> 15000 | F112: ='ESTADOS FINANCIEROS'!G30 -> 121000 | G112: ='ESTADOS FINANCIEROS'!H30 -> 15000000
A113: abc | B113: 2 | C113: 3 | D113: 2 | E113: 4 | F113: 4 | G113: 1
A114: de | B114: 3 | C114: 1 | D114: 2 | E114: 4 | F114: 4 | G114: 1
...

Sheet SUBCUENTAS PASIVO
A3: SUBCUENTAS - DETALLE ESTADOS FINANCIEROS
A5: SUBCUENTA | B5: Fecha corte año anterior | C5: Fecha corte año anterior | D5: Fecha corte año anterior | E5: AJUSTES / RECLASIFICACIONES | G5: Fecha corte año actual
A6: Descripción | B6: Al 01/01/2023 | C6: Al 31/07/2023 | D6: Al 31/12/2023 | E6: Debe | F6: Haber | G6: Al 31/12/2024
A7: PASIVO
A8: Pasivos2 | B8: 150 | C8: 150 | D8: 150 | E8: 150 | F8: 150 | G8: 150
A9: pa1 | B9: 100 | C9: 100 | D9: 100 | E9: 100 | F9: 100 | G9: 100 | I9: Nota aquí que el excel funcione para aumentar mas subcuentas en cada cuenta
A10: pa2 | B10: 50 | C10: 50 | D10: 50 | E10: 50 | F10: 50 | G10: 50
I11: igual en Cedulsa Sumarias seria lo mismo que cuando aumente automaticamente el excel del sistema aumente o disminuya
A15: Total Pasivos2 | B15: =SUM(B9:B10) -> 150 | C15: =SUM(C9:C10) -> 150 | D15: =SUM(D9:D10) -> 150 | E15: =SUM(E9:E10) -> 150 | F15: =SUM(F9:F10) -> 150 | G15: =SUM(G9:G10) -> 150
A17: Pasivos3 | B17: 150 | C17: 150 | D17: 150 | E17: 150 | F17: 150 | G17: 150
A18: pa3 | B18: 100 | C18: 100 | D18: 100 | E18: 100 | F18: 100 | G18: 100
A19: pa4 | B19: 25 | C19: 50 | D19: 50 | E19: 50 | F19: 50 | G19: 50
J24: }
B25: =SUM(B18:B24) -> 125 | C25: =SUM(C18:C24) -> 150 | D25: =SUM(D18:D24) -> 150 | E25: =SUM(E18:E24) -> 150 | F25: =SUM(F18:F24) -> 150 | G25: =SUM(G18:G24) -> 150
A26: Total Pasivos3 | B26: =SUM(B18:B20) -> 125 | C26: =SUM(C18:C20) -> 150 | D26: =SUM(D18:D20) -> 150 | E26: =SUM(E18:E20) -> 150 | F26: =SUM(F18:F20) -> 150 | G26: =SUM(G18:G20) -> 150
B37: =SUM(B36,B31) -> 0 | C37: =SUM(C29:C31) -> 0 | D37: =SUM(D29:D31) -> 0 | E37: =SUM(E29:E31) -> 0 | F37: =SUM(F29:F31) -> 0 | G37: =SUM(G29:G31) -> 0
I40: según necesidad de la persona
A56: XXXXXXXXX | B56: =SUM(B40:B55) -> 0 | C56: =SUM(C40:C55) -> 0 | D56: =SUM(D40:D55) -> 0 | E56: =SUM(E40:E55) -> 0 | F56: =SUM(F40:F55) -> 0 | G56: =SUM(G40:G55) -> 0
B58: ='ESTADOS FINANCIEROS'!C49 -> 48000 | C58: ='ESTADOS FINANCIEROS'!D49 -> 1110000 | D58: ='ESTADOS FINANCIEROS'!E49 -> 2550000 | E58: ='ESTADOS FINANCIEROS'!F49 -> 0 | F58: ='ESTADOS FINANCIEROS'!G49 -> 0 | G58: ='ESTADOS FINANCIEROS'!H49 -> 45000000
A74: XXXXXXXXX | B74: =SUM(B58:B73) -> 48000 | C74: =SUM(C58:C73) -> 1110000 | D74: =SUM(D58:D73) -> 2550000 | E74: =SUM(E58:E73) -> 0 | F74: =SUM(F58:F73) -> 0 | G74: =SUM(G58:G73) -> 45000000
A77: XXXX | B77: ='ESTADOS FINANCIEROS'!C69 -> 0 | C77: ='ESTADOS FINANCIEROS'!D69 -> 0 | D77: ='ESTADOS FINANCIEROS'!E69 -> 0 | E77: ='ESTADOS FINANCIEROS'!F69 -> 0 | F77: ='ESTADOS FINANCIEROS'!G69 -> 0 | G77: ='ESTADOS FINANCIEROS'!H69 -> 0
A94: XXXXXXXXX | B94: =SUM(B77:B93) -> 0 | C94: =SUM(C77:C93) -> 0 | D94: =SUM(D77:D93) -> 0 | E94: =SUM(E77:E93) -> 0 | F94: =SUM(F77:F93) -> 0 | G94: =SUM(G77:G93) -> 0
A96: XXXX | B96: ='ESTADOS FINANCIEROS'!C88 -> 0 | C96: ='ESTADOS FINANCIEROS'!D88 -> 0 | D96: ='ESTADOS FINANCIEROS'!E88 -> 0 | E96: ='ESTADOS FINANCIEROS'!F88 -> 0 | F96: ='ESTADOS FINANCIEROS'!G88 -> 0 | G96: ='ESTADOS FINANCIEROS'!H88 -> 0
A113: XXXXXXXXX | B113: =SUM(B96:B112) -> 0 | C113: =SUM(C96:C112) -> 0 | D113: =SUM(D96:D112) -> 0 | E113: =SUM(E96:E112) -> 0 | F113: =SUM(F96:F112) -> 0 | G113: =SUM(G96:G112) -> 0
A117: XXXX | B117: ='ESTADOS FINANCIEROS'!C104 -> 0 | C117: ='ESTADOS FINANCIEROS'!D104 -> 0 | D117: ='ESTADOS FINANCIEROS'!E104 -> 0 | E117: ='ESTADOS FINANCIEROS'!F104 -> 0 | F117: ='ESTADOS FINANCIEROS'!G104 -> 0 | G117: ='ESTADOS FINANCIEROS'!H104 -> 0
A134: XXXXXXXXX | B134: =SUM(B117:B133) -> 0 | C134: =SUM(C117:C133) -> 0 | D134: =SUM(D117:D133) -> 0 | E134: =SUM(E117:E133) -> 0 | F134: =SUM(F117:F133) -> 0 | G134: =SUM(G117:G133) -> 0
A136: XXXX | B136: ='ESTADOS FINANCIEROS'!C123 -> 0 | C136: ='ESTADOS FINANCIEROS'!D123 -> 0 | D136: ='ESTADOS FINANCIEROS'!E123 -> 0 | E136: ='ESTADOS FINANCIEROS'!F123 -> 0 | F136: ='ESTADOS FINANCIEROS'!G123 -> 0 | G136: ='ESTADOS FINANCIEROS'!H123 -> 0
A153: XXXXXXXXX | B153: =SUM(B136:B152) -> 0 | C153: =SUM(C136:C152) -> 0 | D153: =SUM(D136:D152) -> 0 | E153: =SUM(E136:E152) -> 0 | F153: =SUM(F136:F152) -> 0 | G153: =SUM(G136:G152) -> 0
A157: XXXX | B157: ='ESTADOS FINANCIEROS'!C144 -> 0 | C157: ='ESTADOS FINANCIEROS'!D144 -> 0 | D157: ='ESTADOS FINANCIEROS'!E144 -> 0 | E157: ='ESTADOS FINANCIEROS'!F144 -> 0 | F157: ='ESTADOS FINANCIEROS'!G144 -> 0 | G157: ='ESTADOS FINANCIEROS'!H144 -> 0
A174: XXXXXXXXX | B174: =SUM(B157:B173) -> 0 | C174: =SUM(C157:C173) -> 0 | D174: =SUM(D157:D173) -> 0 | E174: =SUM(E157:E173) -> 0 | F174: =SUM(F157:F173) -> 0 | G174: =SUM(G157:G173) -> 0
A176: XXXX | B176: ='ESTADOS FINANCIEROS'!C163 -> 0 | C176: ='ESTADOS FINANCIEROS'!D163 -> 0 | D176: ='ESTADOS FINANCIEROS'!E163 -> 0 | E176: ='ESTADOS FINANCIEROS'!F163 -> 0 | F176: ='ESTADOS FINANCIEROS'!G163 -> 0 | G176: ='ESTADOS FINANCIEROS'!H163 -> 0
A193: XXXXXXXXX | B193: =SUM(B176:B192) -> 0 | C193: =SUM(C176:C192) -> 0 | D193: =SUM(D176:D192) -> 0 | E193: =SUM(E176:E192) -> 0 | F193: =SUM(F176:F192) -> 0 | G193: =SUM(G176:G192) -> 0
A197: XXXX | B197: ='ESTADOS FINANCIEROS'!C184 -> 0 | C197: ='ESTADOS FINANCIEROS'!D184 -> 0 | D197: ='ESTADOS FINANCIEROS'!E184 -> 0 | E197: ='ESTADOS FINANCIEROS'!F184 -> 0 | F197: ='ESTADOS FINANCIEROS'!G184 -> 0 | G197: ='ESTADOS FINANCIEROS'!H184 -> 0
A214: XXXXXXXXX | B214: =SUM(B197:B213) -> 0 | C214: =SUM(C197:C213) -> 0 | D214: =SUM(D197:D213) -> 0 | E214: =SUM(E197:E213) -> 0 | F214: =SUM(F197:F213) -> 0 | G214: =SUM(G197:G213) -> 0
A216: XXXX | B216: ='ESTADOS FINANCIEROS'!C203 -> 0 | C216: ='ESTADOS FINANCIEROS'!D203 -> 0 | D216: ='ESTADOS FINANCIEROS'!E203 -> 0 | E216: ='ESTADOS FINANCIEROS'!F203 -> 0 | F216: ='ESTADOS FINANCIEROS'!G203 -> 0 | G216: ='ESTADOS FINANCIEROS'!H203 -> 0
A233: XXXXXXXXX | B233: =SUM(B216:B232) -> 0 | C233: =SUM(C216:C232) -> 0 | D233: =SUM(D216:D232) -> 0 | E233: =SUM(E216:E232) -> 0 | F233: =SUM(F216:F232) -> 0 | G233: =SUM(G216:G232) -> 0
A236: XXXX | B236: ='ESTADOS FINANCIEROS'!C223 -> 0 | C236: ='ESTADOS FINANCIEROS'!D223 -> 0 | D236: ='ESTADOS FINANCIEROS'!E223 -> 0 | E236: ='ESTADOS FINANCIEROS'!F223 -> 0 | F236: ='ESTADOS FINANCIEROS'!G223 -> 0 | G236: ='ESTADOS FINANCIEROS'!H223 -> 0
A253: XXXXXXXXX | B253: =SUM(B236:B252) -> 0 | C253: =SUM(C236:C252) -> 0 | D253: =SUM(D236:D252) -> 0 | E253: =SUM(E236:E252) -> 0 | F253: =SUM(F236:F252) -> 0 | G253: =SUM(G236:G252) -> 0
A255: XXXX | B255: ='ESTADOS FINANCIEROS'!C242 -> 0 | C255: ='ESTADOS FINANCIEROS'!D242 -> 0 | D255: ='ESTADOS FINANCIEROS'!E242 -> 0 | E255: ='ESTADOS FINANCIEROS'!F242 -> 0 | F255: ='ESTADOS FINANCIEROS'!G242 -> 0 | G255: ='ESTADOS FINANCIEROS'!H242 -> 0
A272: XXXXXXXXX | B272: =SUM(B255:B271) -> 0 | C272: =SUM(C255:C271) -> 0 | D272: =SUM(D255:D271) -> 0 | E272: =SUM(E255:E271) -> 0 | F272: =SUM(F255:F271) -> 0 | G272: =SUM(G255:G271) -> 0
...

Sheet SUBCUENTAS PATRIMONIO
A3: SUBCUENTAS - DETALLE ESTADOS FINANCIEROS
A5: SUBCUENTA | B5: Fecha corte año anterior | C5: Fecha corte año anterior | D5: Fecha corte año anterior | E5: AJUSTES / RECLASIFICACIONES | G5: Fecha corte año actual
A6: Descripción | B6: Al 01/01/2023 | C6: Al 31/07/2023 | D6: Al 31/12/2023 | E6: Debe | F6: Haber | G6: Al 31/12/2024
A7: PATRIMONIO
A8: Capital Social | B8: 150 | C8: 150 | D8: 150 | E8: 150 | F8: 150 | G8: 150
A9: Capital Autorizado | I9: Nota aquí que el excel funcione para aumentar mas subcuentas en cada cuenta
A10: Capital Suscrito y Pagado
I11: igual en Cedulsa Sumarias seria lo mismo que cuando aumente automaticamente el excel del sistema aumente o disminuya
A15: Total Capital Social | B15: =SUM(B9:B10) -> 0 | C15: =SUM(C9:C10) -> 0 | D15: =SUM(D9:D10) -> 0 | E15: =SUM(E9:E10) -> 0 | F15: =SUM(F9:F10) -> 0 | G15: =SUM(G9:G10) -> 0
A17: Reservas | B17: 150 | C17: 150 | D17: 150 | E17: 150 | F17: 150 | G17: 150
A18: Reserva Legal
A19: Reservas Estatutarias
A20: Reservas Ocasionales
J24: }
B25: =SUM(B18:B24) -> 0 | C25: =SUM(C18:C24) -> 0 | D25: =SUM(D18:D24) -> 0 | E25: =SUM(E18:E24) -> 0 | F25: =SUM(F18:F24) -> 0 | G25: =SUM(G18:G24) -> 0
A26: Total Reservas | B26: =SUM(B18:B20) -> 0 | C26: =SUM(C18:C20) -> 0 | D26: =SUM(D18:D20) -> 0 | E26: =SUM(E18:E20) -> 0 | F26: =SUM(F18:F20) -> 0 | G26: =SUM(G18:G20) -> 0
A28: Resultados | B28: 150 | C28: 150 | D28: 150 | E28: 150 | F28: 150 | G28: 150
A29: Utilidades Acumuladas | B29: 100 | C29: 100 | D29: 100 | E29: 100 | F29: 100 | G29: 100
A30: Utilidad del Ejercicio | B30: 50 | C30: 50 | D30: 50 | E30: 50 | F30: 50 | G30: 50
A31: Pérdidas Acumuladas (-) | B31: =SUM(B29:B30) -> 150 | C31: =SUM(C29:C30) -> 150 | D31: =SUM(D29:D30) -> 150 | E31: =SUM(E29:E30) -> 150 | F31: =SUM(F29:F30) -> 150 | G31: =SUM(G29:G30) -> 150
A37: Total Resultados | B37: =SUM(B36,B31) -> 150 | C37: =SUM(C29:C31) -> 300 | D37: =SUM(D29:D31) -> 300 | E37: =SUM(E29:E31) -> 300 | F37: =SUM(F29:F31) -> 300 | G37: =SUM(G29:G31) -> 300
A40: Patrimonio1 | B40: 100 | C40: ='ESTADOS FINANCIEROS'!D30 -> 370000 | D40: ='ESTADOS FINANCIEROS'!E30 -> 850000 | E40: ='ESTADOS FINANCIEROS'!F30 -> 15000 | F40: ='ESTADOS FINANCIEROS'!G30 -> 121000 | G40: ='ESTADOS FINANCIEROS'!H30 -> 15000000 | I40: según necesidad de la persona
A41: pat1
A42: pat2
A56: Patrimonio1 | B56: =SUM(B40:B55) -> 100 | C56: =SUM(C40:C55) -> 370000 | D56: =SUM(D40:D55) -> 850000 | E56: =SUM(E40:E55) -> 15000 | F56: =SUM(F40:F55) -> 121000 | G56: =SUM(G40:G55) -> 15000000
A58: Patrimonio2 | B58: ='ESTADOS FINANCIEROS'!C49 -> 48000 | C58: ='ESTADOS FINANCIEROS'!D49 -> 1110000 | D58: ='ESTADOS FINANCIEROS'!E49 -> 2550000 | E58: ='ESTADOS FINANCIEROS'!F49 -> 0 | F58: ='ESTADOS FINANCIEROS'!G49 -> 0 | G58: ='ESTADOS FINANCIEROS'!H49 -> 45000000
A59: Pat3
A60: Pat4
A74: Patrimonio2 | B74: =SUM(B58:B73) -> 48000 | C74: =SUM(C58:C73) -> 1110000 | D74: =SUM(D58:D73) -> 2550000 | E74: =SUM(E58:E73) -> 0 | F74: =SUM(F58:F73) -> 0 | G74: =SUM(G58:G73) -> 45000000
A77: XXXX | B77: ='ESTADOS FINANCIEROS'!C69 -> 0 | C77: ='ESTADOS FINANCIEROS'!D69 -> 0 | D77: ='ESTADOS FINANCIEROS'!E69 -> 0 | E77: ='ESTADOS FINANCIEROS'!F69 -> 0 | F77: ='ESTADOS FINANCIEROS'!G69 -> 0 | G77: ='ESTADOS FINANCIEROS'!H69 -> 0
A94: XXXXXXXXX | B94: =SUM(B77:B93) -> 0 | C94: =SUM(C77:C93) -> 0 | D94: =SUM(D77:D93) -> 0 | E94: =SUM(E77:E93) -> 0 | F94: =SUM(F77:F93) -> 0 | G94: =SUM(G77:G93) -> 0
A96: XXXX | B96: ='ESTADOS FINANCIEROS'!C88 -> 0 | C96: ='ESTADOS FINANCIEROS'!D88 -> 0 | D96: ='ESTADOS FINANCIEROS'!E88 -> 0 | E96: ='ESTADOS FINANCIEROS'!F88 -> 0 | F96: ='ESTADOS FINANCIEROS'!G88 -> 0 | G96: ='ESTADOS FINANCIEROS'!H88 -> 0
A113: XXXXXXXXX | B113: =SUM(B96:B112) -> 0 | C113: =SUM(C96:C112) -> 0 | D113: =SUM(D96:D112) -> 0 | E113: =SUM(E96:E112) -> 0 | F113: =SUM(F96:F112) -> 0 | G113: =SUM(G96:G112) -> 0
A117: XXXX | B117: ='ESTADOS FINANCIEROS'!C104 -> 0 | C117: ='ESTADOS FINANCIEROS'!D104 -> 0 | D117: ='ESTADOS FINANCIEROS'!E104 -> 0 | E117: ='ESTADOS FINANCIEROS'!F104 -> 0 | F117: ='ESTADOS FINANCIEROS'!G104 -> 0 | G117: ='ESTADOS FINANCIEROS'!H104 -> 0
A134: XXXXXXXXX | B134: =SUM(B117:B133) -> 0 | C134: =SUM(C117:C133) -> 0 | D134: =SUM(D117:D133) -> 0 | E134: =SUM(E117:E133) -> 0 | F134: =SUM(F117:F133) -> 0 | G134: =SUM(G117:G133) -> 0
A136: XXXX | B136: ='ESTADOS FINANCIEROS'!C123 -> 0 | C136: ='ESTADOS FINANCIEROS'!D123 -> 0 | D136: ='ESTADOS FINANCIEROS'!E123 -> 0 | E136: ='ESTADOS FINANCIEROS'!F123 -> 0 | F136: ='ESTADOS FINANCIEROS'!G123 -> 0 | G136: ='ESTADOS FINANCIEROS'!H123 -> 0
A153: XXXXXXXXX | B153: =SUM(B136:B152) -> 0 | C153: =SUM(C136:C152) -> 0 | D153: =SUM(D136:D152) -> 0 | E153: =SUM(E136:E152) -> 0 | F153: =SUM(F136:F152) -> 0 | G153: =SUM(G136:G152) -> 0
A157: XXXX | B157: ='ESTADOS FINANCIEROS'!C144 -> 0 | C157: ='ESTADOS FINANCIEROS'!D144 -> 0 | D157: ='ESTADOS FINANCIEROS'!E144 -> 0 | E157: ='ESTADOS FINANCIEROS'!F144 -> 0 | F157: ='ESTADOS FINANCIEROS'!G144 -> 0 | G157: ='ESTADOS FINANCIEROS'!H144 -> 0
A174: XXXXXXXXX | B174: =SUM(B157:B173) -> 0 | C174: =SUM(C157:C173) -> 0 | D174: =SUM(D157:D173) -> 0 | E174: =SUM(E157:E173) -> 0 | F174: =SUM(F157:F173) -> 0 | G174: =SUM(G157:G173) -> 0
A176: XXXX | B176: ='ESTADOS FINANCIEROS'!C163 -> 0 | C176: ='ESTADOS FINANCIEROS'!D163 -> 0 | D176: ='ESTADOS FINANCIEROS'!E163 -> 0 | E176: ='ESTADOS FINANCIEROS'!F163 -> 0 | F176: ='ESTADOS FINANCIEROS'!G163 -> 0 | G176: ='ESTADOS FINANCIEROS'!H163 -> 0
...

Sheet SUBCUENTAS RESULTADOS
A3: SUBCUENTAS - DETALLE ESTADOS FINANCIEROS
A5: SUBCUENTA | B5: Fecha corte año anterior | C5: Fecha corte año anterior | D5: Fecha corte año anterior | E5: AJUSTES / RECLASIFICACIONES | G5: Fecha corte año actual
A6: Descripción | B6: Al 01/01/2023 | C6: Al 31/07/2023 | D6: Al 31/12/2023 | E6: Debe | F6: Haber | G6: Al 31/12/2024
A7: ESTADO DE RESULTADOS
A8: Ingresos | B8: 150 | C8: 150 | D8: 150 | E8: 150 | F8: 150 | G8: 150
A9: Ventas Nacionales | B9: 1 | C9: 1 | D9: 1 | E9: 1 | F9: 1 | G9: 1 | I9: Nota aquí que el excel funcione para aumentar mas subcuentas en cada cuenta
A10: Ventas Exportación | B10: 1 | C10: 1 | D10: 1 | E10: 1 | F10: 1 | G10: 1
A11: Otros Ingresos | B11: 1 | C11: 1 | D11: 1 | E11: 1 | F11: 1 | G11: 1 | I11: igual en Cedulsa Sumarias seria lo mismo que cuando aumente automaticamente el excel del sistema aumente o disminuya
A17: Total Ingresos | B17: =SUM(B8:B16) -> 153 | C17: =SUM(C8:C16) -> 153 | D17: =SUM(D8:D16) -> 153 | E17: =SUM(E8:E16) -> 153 | F17: =SUM(F8:F16) -> 153 | G17: =SUM(G8:G16) -> 153
A19: Costos y Gastos | B19: 150 | C19: 150 | D19: 150 | E19: 150 | F19: 150 | G19: 150
A20: Costo de Ventas
A21: Gastos de Administración
A22: Gastos de Ventas
A23: Gastos Financieros
A31: Total Costos y Gastos | B31: =SUM(B19:B23) -> 150 | C31: =SUM(C19:C23) -> 150 | D31: =SUM(D19:D23) -> 150 | E31: =SUM(E19:E23) -> 150 | F31: =SUM(F19:F23) -> 150 | G31: =SUM(G19:G23) -> 150
A33: Estado1 | B33: 100 | C33: ='ESTADOS FINANCIEROS'!D10 -> 370000 | D33: ='ESTADOS FINANCIEROS'!E10 -> 850000 | E33: ='ESTADOS FINANCIEROS'!F10 -> 15000 | F33: ='ESTADOS FINANCIEROS'!G10 -> 121000 | G33: ='ESTADOS FINANCIEROS'!H10 -> 15000000
A34: es1 | B34: 1 | C34: 2 | D34: 3 | E34: 4 | F34: 5 | G34: 6
A35: es2 | B35: 1 | C35: 2 | D35: 3 | E35: 4 | F35: 5 | G35: 6
A36: es3 | B36: 1 | C36: 2 | D36: 3 | E36: 4 | F36: 5 | G36: 6 | J36: }
A50: Estado1 | B50: =SUM(B33:B49) -> 103 | C50: =SUM(C33:C49) -> 370006 | D50: =SUM(D33:D49) -> 850009 | E50: =SUM(E33:E49) -> 15012 | F50: =SUM(F33:F49) -> 121015 | G50: =SUM(G33:G49) -> 15000018
A52: Estado2 | B52: ='ESTADOS FINANCIEROS'!C29 -> 15000 | C52: ='ESTADOS FINANCIEROS'!D29 -> 370000 | D52: ='ESTADOS FINANCIEROS'!E29 -> 850000 | E52: ='ESTADOS FINANCIEROS'!F29 -> 15000 | F52: ='ESTADOS FINANCIEROS'!G29 -> 121000 | G52: ='ESTADOS FINANCIEROS'!H29 -> 15000000 | I52: según necesidad de la persona
A53: ET1 | B53: 1 | C53: 2 | D53: 3 | E53: 4 | F53: 5 | G53: 6
A54: ET2 | B54: 1 | C54: 2 | D54: 3 | E54: 4 | F54: 5 | G54: 6
A55: ET3 | B55: 1 | C55: 2 | D55: 3 | E55: 4 | F55: 5 | G55: 6
A69: Estado2 | B69: =SUM(B52:B68) -> 15003 | C69: =SUM(C52:C68) -> 370006 | D69: =SUM(D52:D68) -> 850009 | E69: =SUM(E52:E68) -> 15012 | F69: =SUM(F52:F68) -> 121015 | G69: =SUM(G52:G68) -> 15000018
A72: XXXX | B72: ='ESTADOS FINANCIEROS'!C49 -> 48000 | C72: ='ESTADOS FINANCIEROS'!D49 -> 1110000 | D72: ='ESTADOS FINANCIEROS'!E49 -> 2550000 | E72: ='ESTADOS FINANCIEROS'!F49 -> 0 | F72: ='ESTADOS FINANCIEROS'!G49 -> 0 | G72: ='ESTADOS FINANCIEROS'!H49 -> 45000000
A89: XXXXXXXXX | B89: =SUM(B72:B88) -> 48000 | C89: =SUM(C72:C88) -> 1110000 | D89: =SUM(D72:D88) -> 2550000 | E89: =SUM(E72:E88) -> 0 | F89: =SUM(F72:F88) -> 0 | G89: =SUM(G72:G88) -> 45000000
A91: XXXX | B91: ='ESTADOS FINANCIEROS'!C68 -> 0 | C91: ='ESTADOS FINANCIEROS'!D68 -> 0 | D91: ='ESTADOS FINANCIEROS'!E68 -> 0 | E91: ='ESTADOS FINANCIEROS'!F68 -> 0 | F91: ='ESTADOS FINANCIEROS'!G68 -> 0 | G91: ='ESTADOS FINANCIEROS'!H68 -> 0
A108: XXXXXXXXX | B108: =SUM(B91:B107) -> 0 | C108: =SUM(C91:C107) -> 0 | D108: =SUM(D91:D107) -> 0 | E108: =SUM(E91:E107) -> 0 | F108: =SUM(F91:F107) -> 0 | G108: =SUM(G91:G107) -> 0
A112: XXXX | B112: ='ESTADOS FINANCIEROS'!C89 -> 0 | C112: ='ESTADOS FINANCIEROS'!D89 -> 0 | D112: ='ESTADOS FINANCIEROS'!E89 -> 0 | E112: ='ESTADOS FINANCIEROS'!F89 -> 0 | F112: ='ESTADOS FINANCIEROS'!G89 -> 0 | G112: ='ESTADOS FINANCIEROS'!H89 -> 0
A129: XXXXXXXXX | B129: =SUM(B112:B128) -> 0 | C129: =SUM(C112:C128) -> 0 | D129: =SUM(D112:D128) -> 0 | E129: =SUM(E112:E128) -> 0 | F129: =SUM(F112:F128) -> 0 | G129: =SUM(G112:G128) -> 0
A131: XXXX | B131: ='ESTADOS FINANCIEROS'!C103 -> 0 | C131: ='ESTADOS FINANCIEROS'!D103 -> 0 | D131: ='ESTADOS FINANCIEROS'!E103 -> 0 | E131: ='ESTADOS FINANCIEROS'!F103 -> 0 | F131: ='ESTADOS FINANCIEROS'!G103 -> 0 | G131: ='ESTADOS FINANCIEROS'!H103 -> 0
A148: XXXXXXXXX | B148: =SUM(B131:B147) -> 0 | C148: =SUM(C131:C147) -> 0 | D148: =SUM(D131:D147) -> 0 | E148: =SUM(E131:E147) -> 0 | F148: =SUM(F131:F147) -> 0 | G148: =SUM(G131:G147) -> 0
A152: XXXX | B152: ='ESTADOS FINANCIEROS'!C124 -> 0 | C152: ='ESTADOS FINANCIEROS'!D124 -> 0 | D152: ='ESTADOS FINANCIEROS'!E124 -> 0 | E152: ='ESTADOS FINANCIEROS'!F124 -> 0 | F152: ='ESTADOS FINANCIEROS'!G124 -> 0 | G152: ='ESTADOS FINANCIEROS'!H124 -> 0
A169: XXXXXXXXX | B169: =SUM(B152:B168) -> 0 | C169: =SUM(C152:C168) -> 0 | D169: =SUM(D152:D168) -> 0 | E169: =SUM(E152:E168) -> 0 | F169: =SUM(F152:F168) -> 0 | G169: =SUM(G152:G168) -> 0
A171: XXXX | B171: ='ESTADOS FINANCIEROS'!C143 -> 0 | C171: ='ESTADOS FINANCIEROS'!D143 -> 0 | D171: ='ESTADOS FINANCIEROS'!E143 -> 0 | E171: ='ESTADOS FINANCIEROS'!F143 -> 0 | F171: ='ESTADOS FINANCIEROS'!G143 -> 0 | G171: ='ESTADOS FINANCIEROS'!H143 -> 0
A188: XXXXXXXXX | B188: =SUM(B171:B187) -> 0 | C188: =SUM(C171:C187) -> 0 | D188: =SUM(D171:D187) -> 0 | E188: =SUM(E171:E187) -> 0 | F188: =SUM(F171:F187) -> 0 | G188: =SUM(G171:G187) -> 0
A192: XXXX | B192: ='ESTADOS FINANCIEROS'!C164 -> 0 | C192: ='ESTADOS FINANCIEROS'!D164 -> 0 | D192: ='ESTADOS FINANCIEROS'!E164 -> 0 | E192: ='ESTADOS FINANCIEROS'!F164 -> 0 | F192: ='ESTADOS FINANCIEROS'!G164 -> 0 | G192: ='ESTADOS FINANCIEROS'!H164 -> 0
A209: XXXXXXXXX | B209: =SUM(B192:B208) -> 0 | C209: =SUM(C192:C208) -> 0 | D209: =SUM(D192:D208) -> 0 | E209: =SUM(E192:E208) -> 0 | F209: =SUM(F192:F208) -> 0 | G209: =SUM(G192:G208) -> 0
A211: XXXX | B211: ='ESTADOS FINANCIEROS'!C183 -> 0 | C211: ='ESTADOS FINANCIEROS'!D183 -> 0 | D211: ='ESTADOS FINANCIEROS'!E183 -> 0 | E211: ='ESTADOS FINANCIEROS'!F183 -> 0 | F211: ='ESTADOS FINANCIEROS'!G183 -> 0 | G211: ='ESTADOS FINANCIEROS'!H183 -> 0
...
