Workbook

Sheet ÍNDICE
A1: Auditoría y Revisoría Fiscal
A2: FASE | B2: REFERENCIA | C2: DESCRIPCIÓN | D2: ACCESO
C3: PASIVOS
B4: PF | C4: Programa | D4: IR A HOJA >>
B5: F-SUM | C5: Cédula sumaria de pasivos | D5: IR A HOJA >>
B6: F-1 | C6: Confirmación de obligaciones financieras | D6: IR A HOJA >>
B7: F-1.1 | C7: Análisis de créditos bancarios | D7: IR A HOJA >>
B8: F-1.2 | C8: Análisis de leasing financiero | D8: IR A HOJA >>
B9: F-1.3 | C9: Verificación de tasas de interés | D9: IR A HOJA >>
B10: F-2 | C10: Proveedores y cuentas por pagar | D10: IR A HOJA >>
B11: F-2.1 | C11: Circularización de proveedores | D11: IR A HOJA >>
B12: F-2.2 | C12: Análisis de antigüedad de proveedores | D12: IR A HOJA >>
B13: F-3 | C13: Costos y gastos por pagar | D13: IR A HOJA >>
B14: F-4 | C14: Obligaciones laborales | D14: IR A HOJA >>
B15: F-4.1 | C15: Cálculo de prestaciones sociales | D15: IR A HOJA >>
... B20: F-7 | C20: Impuestos, gravámenes y tasas | D20: IR A HOJA >>

Sheet PF PROGRAMA
A3: Entidad XXXXXXX | J3: PF
A4: Revisoría Fiscal
A5: Del 01 de Enero al 31 de Diciembre de 2024
A6: Cifras expresadas en [MONEDA]
I8: Auditor
A9: PROGRAMA DE AUDITORÍA - PASIVOS | I9: Fecha Elaboración
I10: Supervisor
A11: ÁREA: | B11: Pasivos | I11: Fecha Aprobación
A12: CUENTA: | B12: F - Pasivos Corrientes y No Corrientes
A13: RESPONSABLE:
A15: OBJETIVO GENERAL
A16: Obtener evidencia de auditoría suficiente y adecuada sobre la existencia, integridad, valuación y presentación de los pasivos conforme a las NIA 500, 501, 505 y 510.
A19: OBJETIVOS ESPECÍFICOS
A20: • | B20: Verificar la existencia y valuación de obligaciones financieras
A21: • | B21: Confirmar saldos de proveedores mediante circularización
A22: • | B22: Evaluar el cálculo de obligaciones laborales y parafiscales
A23: • | B23: Verificar provisiones y pasivos contingentes
A24: • | B24: Revisar el cálculo y pago de impuestos
A25: • | B25: Verificar el cumplimiento de controles internos
A27: No. | B27: REF. | C27: PROCEDIMIENTO | D27: HECHO | E27: FECHA | F27: REVISADO | G27: FECHA | H27: VÍNCULO
A28: 1 | B28: F-SUM | C28: Prepare la cédula sumaria de pasivos | H28: VER >>
A29: 2 | B29: F-1 | C29: Confirme obligaciones financieras con entidades | H29: VER >>
A30: 3 | B30: F-1.1 | C30: Analice créditos bancarios vigentes | H30: VER >>
A31: 4 | B31: F-1.2 | C31: Revise contratos de leasing financiero | H31: VER >>
A32: 5 | B32: F-1.3 | C32: Verifique tasas de interés aplicadas | H32: VER >>
A33: 6 | B33: F-2 | C33: Analice cuentas por pagar a proveedores | H33: VER >>
A34: 7 | B34: F-2.1 | C34: Circularice proveedores principales | H34: VER >>
A35: 8 | B35: F-2.2 | C35: Evalúe antigüedad de cuentas por pagar | H35: VER >>
A36: 9 | B36: F-3 | C36: Verifique costos y gastos por pagar | H36: VER >>
A37: 10 | B37: F-4 | C37: Analice obligaciones laborales | H37: VER >>
A38: 11 | B38: F-4.1 | C38: Recalcule prestaciones sociales | H38: VER >>
A39: 12 | B39: F-4.2 | C39: Verifique cálculos de nómina | H39: VER >>
... A43: 16 | B43: F-7 | C43: Verifique cálculo y pago de impuestos | H43: VER >>
A46: CONCLUSIÓN DEL PROGRAMA
A47: Basado en los procedimientos ejecutados, concluimos que:
A56: Preparado por: Firma | F56: Revisado por:
A57: Nombre | F57: Nombre
A71: << Volver al Índice

Sheet F-SUM Sumaria
A1: << Volver al Índice
J3: F-SUM
D5: abac, s. a. | E5: Entidad XXXXXXX | I5: Auditor
E6: Revisoría Fiscal | I6: Fecha Elaboración
E7: Del 01 de Enero al 31 de Diciembre de 2024 | I7: Supervisor
E8: Cifras expresadas en [MONEDA] | I8: Fecha Aprobación
A10: CÉDULA SUMARIA DE PASIVOS
A13: Clasificación | B13: Saldo Inicial | C13: Movimientos Débito | D13: Movimientos Crédito | E13: Saldo Final Libros | F13: Ajustes y Reclas. | G13: Saldo Ajustado | H13: Saldo Auditoría | I13: Diferencia | J13: % Total
A14: Obligaciones Financieras | B14: 100 | C14: 50 | D14: 5 | E14: =B14+C14-D14 -> 145 | G14: =E14+F14 -> 145 | H14: 100 | I14: =H14-G14 -> -45
A15: Proveedores | E15: =B15+C15-D15 -> 0 | G15: =E15+F15 -> 0 | I15: =H15-G15 -> 0
A16: Costos y Gastos por Pagar | E16: =B16+C16-D16 -> 0 | G16: =E16+F16 -> 0 | I16: =H16-G16 -> 0
A17: Obligaciones Laborales | E17: =B17+C17-D17 -> 0 | G17: =E17+F17 -> 0 | I17: =H17-G17 -> 0
A18: Impuestos por Pagar | E18: =B18+C18-D18 -> 0 | G18: =E18+F18 -> 0 | I18: =H18-G18 -> 0
A19: Pasivos Estimados | E19: =B19+C19-D19 -> 0 | G19: =E19+F19 -> 0 | I19: =H19-G19 -> 0
A20: Provisiones | E20: =B20+C20-D20 -> 0 | G20: =E20+F20 -> 0 | I20: =H20-G20 -> 0
A21: Partes Relacionadas | B21: 7 | E21: =B21+C21-D21 -> 7 | G21: =E21+F21 -> 7 | I21: =H21-G21 -> -7
A22: TOTAL PASIVOS | B22: =SUM(B14:B21) -> 107 | C22: =SUM(C14:C21) -> 50 | D22: =SUM(D14:D21) -> 5 | E22: =SUM(E14:E21) -> 152 | F22: =SUM(F14:F21) -> 0 | G22: =SUM(G14:G21) -> 152 | H22: =SUM(H14:H21) -> 100 | I22: =SUM(I14:I21) -> -52 | J22: 1
A34: Preparado por: Firma | F34: Revisado por:
A35: Nombre | F35: Nombre
A42: =HYPERLINK("#'INDICE'!A60","<< Volver al Indice") -> << Volver al Indice

Sheet F-1 Oblig Financ
A1: << Volver al Índice
N4: F-1
F6: Entidad XXXXXXX | M6: Auditor
F7: Revisoría Fiscal | M7: Fecha Elaboración
F8: Del 01 de Enero al 31 de Diciembre de 2024 | M8: Supervisor
F9: Cifras expresadas en [MONEDA] | M9: Fecha Aprobación
A11: F-1: CONFIRMACIÓN DE OBLIGACIONES FINANCIERAS
A13: Objetivo: Verificar existencia, integridad y valuación de obligaciones financieras
A15: Entidad | B15: No. Crédito | C15: Tipo | D15: Monto Original | E15: Tasa % | F15: Plazo | G15: Corto Plazo | H15: Largo Plazo | I15: Total | J15: Confirmado | K15: Garantía | L15: ✓
D16: 100 | E16: 0.08 | F16: 12 | G16: 15 | H16: 24 | I16: 800
I17: =G17+H17 -> 0
I18: =G18+H18 -> 0
I19: =G19+H19 -> 0
I20: =G20+H20 -> 0
I21: =G21+H21 -> 0
I22: =G22+H22 -> 0
I23: =G23+H23 -> 0
I24: =G24+H24 -> 0
I25: =G25+H25 -> 0
I26: =G26+H26 -> 0
I27: =G27+H27 -> 0
I28: =G28+H28 -> 0
... I30: =G30+H30 -> 0
F32: TOTALES: | G32: =SUM(G16:G31) -> 15 | H32: =SUM(H16:H31) -> 24 | I32: =G32+H32 -> 39
A41: Preparado por: Firma | H41: Revisado por:
A42: Nombre | H42: Nombre
A52: =HYPERLINK("#'INDICE'!A61","<< Volver al Indice") -> << Volver al Indice

Sheet F-1.1 Créditos
A1: << Volver al Índice
N4: F-1.1
E6: Entidad XXXXXXX | M6: Auditor
E7: Revisoría Fiscal | M7: Fecha Elaboración
E8: Del 01 de Enero al 31 de Diciembre de 2024 | M8: Supervisor
E9: Cifras expresadas en [MONEDA] | M9: Fecha Aprobación
A12: F-1.1: ANÁLISIS DE CRÉDITOS BANCARIOS
A15: Banco | B15: No. Crédito | C15: Fecha Desemb. | D15: Saldo Inicial | E15: Desembolsos | F15: Pagos Capital | G15: Intereses Pag. | H15: Saldo Final | I15: Tasa | J15: Conciliado | K15: ✓
E16: 800 | F16: 5 | G16: 3 | H16: =D16+E16-F16 -> 795 | I16: 0.05 | J16: =IF(H16=D16+E16-F16,"OK","REVISAR") -> OK
H17: =D17+E17-F17 -> 0 | J17: =IF(H17=D17+E17-F17,"OK","REVISAR") -> OK
H18: =D18+E18-F18 -> 0 | J18: =IF(H18=D18+E18-F18,"OK","REVISAR") -> OK
H19: =D19+E19-F19 -> 0 | J19: =IF(H19=D19+E19-F19,"OK","REVISAR") -> OK
H20: =D20+E20-F20 -> 0 | J20: =IF(H20=D20+E20-F20,"OK","REVISAR") -> OK
H21: =D21+E21-F21 -> 0 | J21: =IF(H21=D21+E21-F21,"OK","REVISAR") -> OK
H22: =D22+E22-F22 -> 0 | J22: =IF(H22=D22+E22-F22,"OK","REVISAR") -> OK
H23: =D23+E23-F23 -> 0 | J23: =IF(H23=D23+E23-F23,"OK","REVISAR") -> OK
H24: =D24+E24-F24 -> 0 | J24: =IF(H24=D24+E24-F24,"OK","REVISAR") -> OK
H25: =D25+E25-F25 -> 0 | J25: =IF(H25=D25+E25-F25,"OK","REVISAR") -> OK
A36: Preparado por: Firma | H36: Revisado por:
A37: Nombre | H37: Nombre
A49: =HYPERLINK("#'INDICE'!A62","<< Volver al Indice") -> << Volver al Indice

Sheet F-1.2 Leasing
A1: << Volver al Índice
N3: F-1.2
F5: Entidad XXXXXXX | M5: Auditor
F6: Revisoría Fiscal | M6: Fecha Elaboración
F7: Del 01 de Enero al 31 de Diciembre de 2024 | M7: Supervisor
F8: Cifras expresadas en [MONEDA] | M8: Fecha Aprobación
A10: F-1.2: ANÁLISIS DE LEASING FINANCIERO
A11: Objetivo: Verificar cumplimiento con NIIF 16 - Arrendamientos
A13: Contrato | B13: Activo | C13: Valor Activo | D13: Tasa Impl. | E13: Plazo Meses | F13: Cuota Mensual | G13: Saldo CP | H13: Saldo LP | I13: Total Pasivo | J13: Venc. Contrato | K13: Cumple NIIF 16 | L13: ✓
I14: =G14+H14 -> 0 | K14: =IF(I14>0,"SÍ","NO") -> NO
I15: =G15+H15 -> 0 | K15: =IF(I15>0,"SÍ","NO") -> NO
I16: =G16+H16 -> 0 | K16: =IF(I16>0,"SÍ","NO") -> NO
I17: =G17+H17 -> 0 | K17: =IF(I17>0,"SÍ","NO") -> NO
I18: =G18+H18 -> 0 | K18: =IF(I18>0,"SÍ","NO") -> NO
I19: =G19+H19 -> 0 | K19: =IF(I19>0,"SÍ","NO") -> NO
I20: =G20+H20 -> 0 | K20: =IF(I20>0,"SÍ","NO") -> NO
F22: TOTALES: | G22: =SUM(G14:G21) -> 0 | H22: =SUM(H14:H21) -> 0 | I22: =G22+H22 -> 0
A35: Preparado por: Firma | H35: Revisado por:
A36: Nombre | H36: Nombre
A42: =HYPERLINK("#'INDICE'!A63","<< Volver al Indice") -> << Volver al Indice

Sheet F-1.3 Tasas
A1: << Volver al Índice
N3: F-1.3
E5: Entidad XXXXXXX | M5: Auditor
E6: Revisoría Fiscal | M6: Fecha Elaboración
E7: Del 01 de Enero al 31 de Diciembre de 2024 | M7: Supervisor
E8: Cifras expresadas en [MONEDA] | M8: Fecha Aprobación
A10: F-1.3: VERIFICACIÓN DE TASAS DE INTERÉS
A13: Obligación | B13: Entidad | C13: Tasa Pactada | D13: Tasa Aplicada | E13: Diferencia | F13: Int. Pagados | G13: Int. Calculados | H13: Diferencia $ | I13: Razonable | J13: ✓
C14: 0.05 | D14: 0.07 | E14: =D14-C14 -> 0.02 | F14: 100 | G14: 50 | H14: =G14-F14 -> -50 | I14: =IF(ABS(H14)<1000,"SÍ","REVISAR") -> SÍ
E15: =D15-C15 -> 0 | H15: =G15-F15 -> 0 | I15: =IF(ABS(H15)<1000,"SÍ","REVISAR") -> SÍ
E16: =D16-C16 -> 0 | H16: =G16-F16 -> 0 | I16: =IF(ABS(H16)<1000,"SÍ","REVISAR") -> SÍ
E17: =D17-C17 -> 0 | H17: =G17-F17 -> 0 | I17: =IF(ABS(H17)<1000,"SÍ","REVISAR") -> SÍ
E18: =D18-C18 -> 0 | H18: =G18-F18 -> 0 | I18: =IF(ABS(H18)<1000,"SÍ","REVISAR") -> SÍ
E19: =D19-C19 -> 0 | H19: =G19-F19 -> 0 | I19: =IF(ABS(H19)<1000,"SÍ","REVISAR") -> SÍ
E20: =D20-C20 -> 0 | H20: =G20-F20 -> 0 | I20: =IF(ABS(H20)<1000,"SÍ","REVISAR") -> SÍ
E21: =D21-C21 -> 0 | H21: =G21-F21 -> 0 | I21: =IF(ABS(H21)<1000,"SÍ","REVISAR") -> SÍ
E22: =D22-C22 -> 0 | H22: =G22-F22 -> 0 | I22: =IF(ABS(H22)<1000,"SÍ","REVISAR") -> SÍ
E23: =D23-C23 -> 0 | H23: =G23-F23 -> 0 | I23: =IF(ABS(H23)<1000,"SÍ","REVISAR") -> SÍ
E24: =D24-C24 -> 0 | H24: =G24-F24 -> 0 | I24: =IF(ABS(H24)<1000,"SÍ","REVISAR") -> SÍ
E25: =D25-C25 -> 0 | H25: =G25-F25 -> 0 | I25: =IF(ABS(H25)<1000,"SÍ","REVISAR") -> SÍ
E26: =D26-C26 -> 0 | H26: =G26-F26 -> 0 | I26: =IF(ABS(H26)<1000,"SÍ","REVISAR") -> SÍ
... E28: =D28-C28 -> 0 | H28: =G28-F28 -> 0 | I28: =IF(ABS(H28)<1000,"SÍ","REVISAR") -> SÍ
A37: Preparado por: Firma | H37: Revisado por:
A38: Nombre | H38: Nombre
A52: =HYPERLINK("#'INDICE'!A64","<< Volver al Indice") -> << Volver al Indice

Sheet F-2 Proveedores
A1: << Volver al Índice
N3: F-2.1
E5: Entidad XXXXXXX | M5: Auditor
E6: Revisoría Fiscal | M6: Fecha Elaboración
E7: Del 01 de Enero al 31 de Diciembre de 2024 | M7: Supervisor
E8: Cifras expresadas en [MONEDA] | M8: Fecha Aprobación
A10: F-2.1: CIRCULARIZACIÓN DE PROVEEDORES
A11: Objetivo: Confirmar saldos con proveedores principales (cobertura mínima 70%)
A13: Proveedor | B13: Saldo Contable | C13: Carta Enviada | D13: Fecha Envío | E13: Respuesta | F13: Saldo Confirmado | G13: Diferencia | H13: Diferencia % | I13: Ajuste | J13: Estado | K13: ✓
B14: 95 | F14: 100 | G14: =F14-B14 -> 5 | H14: =IF(B14=0,0,G14/B14) -> 0.052631579 | J14: =IF(E14="SÍ",IF(ABS(H14)<0.05,"OK","REVISAR"),"PENDIENTE") -> PENDIENTE
G15: =F15-B15 -> 0 | H15: =IF(B15=0,0,G15/B15) -> 0 | J15: =IF(E15="SÍ",IF(ABS(H15)<0.05,"OK","REVISAR"),"PENDIENTE") -> PENDIENTE
G16: =F16-B16 -> 0 | H16: =IF(B16=0,0,G16/B16) -> 0 | J16: =IF(E16="SÍ",IF(ABS(H16)<0.05,"OK","REVISAR"),"PENDIENTE") -> PENDIENTE
G17: =F17-B17 -> 0 | H17: =IF(B17=0,0,G17/B17) -> 0 | J17: =IF(E17="SÍ",IF(ABS(H17)<0.05,"OK","REVISAR"),"PENDIENTE") -> PENDIENTE
G18: =F18-B18 -> 0 | H18: =IF(B18=0,0,G18/B18) -> 0 | J18: =IF(E18="SÍ",IF(ABS(H18)<0.05,"OK","REVISAR"),"PENDIENTE") -> PENDIENTE
G19: =F19-B19 -> 0 | H19: =IF(B19=0,0,G19/B19) -> 0 | J19: =IF(E19="SÍ",IF(ABS(H19)<0.05,"OK","REVISAR"),"PENDIENTE") -> PENDIENTE
G20: =F20-B20 -> 0 | H20: =IF(B20=0,0,G20/B20) -> 0 | J20: =IF(E20="SÍ",IF(ABS(H20)<0.05,"OK","REVISAR"),"PENDIENTE") -> PENDIENTE
G21: =F21-B21 -> 0 | H21: =IF(B21=0,0,G21/B21) -> 0 | J21: =IF(E21="SÍ",IF(ABS(H21)<0.05,"OK","REVISAR"),"PENDIENTE") -> PENDIENTE
G22: =F22-B22 -> 0 | H22: =IF(B22=0,0,G22/B22) -> 0 | J22: =IF(E22="SÍ",IF(ABS(H22)<0.05,"OK","REVISAR"),"PENDIENTE") -> PENDIENTE
G23: =F23-B23 -> 0 | H23: =IF(B23=0,0,G23/B23) -> 0 | J23: =IF(E23="SÍ",IF(ABS(H23)<0.05,"OK","REVISAR"),"PENDIENTE") -> PENDIENTE
G24: =F24-B24 -> 0 | H24: =IF(B24=0,0,G24/B24) -> 0 | J24: =IF(E24="SÍ",IF(ABS(H24)<0.05,"OK","REVISAR"),"PENDIENTE") -> PENDIENTE
G25: =F25-B25 -> 0 | H25: =IF(B25=0,0,G25/B25) -> 0 | J25: =IF(E25="SÍ",IF(ABS(H25)<0.05,"OK","REVISAR"),"PENDIENTE") -> PENDIENTE
G26: =F26-B26 -> 0 | H26: =IF(B26=0,0,G26/B26) -> 0 | J26: =IF(E26="SÍ",IF(ABS(H26)<0.05,"OK","REVISAR"),"PENDIENTE") -> PENDIENTE
... G33: =F33-B33 -> 0 | H33: =IF(B33=0,0,G33/B33) -> 0 | J33: =IF(E33="SÍ",IF(ABS(H33)<0.05,"OK","REVISAR"),"PENDIENTE") -> PENDIENTE
A36: ESTADÍSTICAS DE CIRCULARIZACIÓN:
A37: Total Saldo: | B37: =SUM(B14:B34) -> 95
A38: Cobertura Circularizada: | B38: =IF(B37=0,0,SUMIF(C14:C35,"SÍ",B14:B35)/B37) -> 0
A50: Preparado por: Firma | H50: Revisado por:
A51: Nombre | H51: Nombre
A62: =HYPERLINK("#'INDICE'!A65","<< Volver al Indice") -> << Volver al Indice

Sheet F-2.1 Circular
A1: << Volver al Índice
K3: F-2.2
E5: Entidad XXXXXXX | J5: Auditor
E6: Revisoría Fiscal | J6: Fecha Elaboración
E7: Del 01 de Enero al 31 de Diciembre de 2024 | J7: Supervisor
E8: Cifras expresadas en [MONEDA] | J8: Fecha Aprobación
A10: F-2.2: ANÁLISIS DE ANTIGÜEDAD DE PROVEEDORES
A12: Proveedor | B12: 0-30 días | C12: 31-60 días | D12: 61-90 días | E12: 91-180 días | F12: Más 180 días | G12: Total | H12: Observaciones
B13: 1 | G13: =SUM(B13:F13) -> 1
G14: =SUM(B14:F14) -> 0
G15: =SUM(B15:F15) -> 0
G16: =SUM(B16:F16) -> 0
G17: =SUM(B17:F17) -> 0
G18: =SUM(B18:F18) -> 0
G19: =SUM(B19:F19) -> 0
G20: =SUM(B20:F20) -> 0
G21: =SUM(B21:F21) -> 0
G22: =SUM(B22:F22) -> 0
G23: =SUM(B23:F23) -> 0
G24: =SUM(B24:F24) -> 0
G25: =SUM(B25:F25) -> 0
... G32: =SUM(B32:F32) -> 0
A34: TOTALES | B34: =SUM(B13:B33) -> 1 | C34: =SUM(C13:C33) -> 0 | D34: =SUM(D13:D33) -> 0 | E34: =SUM(E13:E33) -> 0 | F34: =SUM(F13:F33) -> 0 | G34: =SUM(G13:G33) -> 1
A45: Preparado por: Firma | H45: Revisado por:
A46: Nombre | H46: Nombre
A56: =HYPERLINK("#'INDICE'!A66","<< Volver al Indice") -> << Volver al Indice

Sheet COSTOS Y GASTOS
A1: << Volver al Índice
L5: F-3
D6: Entidad XXXXXXX
D7: Revisoría Fiscal | K7: Auditor
D8: Del 01 de Enero al 31 de Diciembre de 2024 | K8: Fecha Elaboración
D9: Cifras expresadas en [MONEDA] | K9: Supervisor
K10: Fecha Aprobación
A12: F-3: COSTOS Y GASTOS POR PAGAR
A15: Concepto | B15: Proveedor | C15: Período | D15: Valor | E15: Devengado | F15: Pagado | G15: Saldo | H15: Soporte | I15: ✓
A16: Servicios públicos | D16: 100 | E16: 50 | F16: 85 | G16: =E16-F16 -> -35
A17: Arrendamientos | G17: =E17-F17 -> 0
A18: Honorarios | G18: =E18-F18 -> 0
A19: Seguros | G19: =E19-F19 -> 0
A20: Mantenimientos | G20: =E20-F20 -> 0
A21: Publicidad | G21: =E21-F21 -> 0
A22: Transporte | G22: =E22-F22 -> 0
A23: Otros | G23: =E23-F23 -> 0
C25: TOTAL: | D25: =SUM(D16:D24) -> 100 | E25: =SUM(E16:E24) -> 50 | F25: =SUM(F16:F24) -> 85 | G25: =SUM(G16:G24) -> -35
A37: Preparado por: Firma | F37: Revisado por:
A38: Nombre | F38: Nombre
A53: =HYPERLINK("#'INDICE'!A67","<< Volver al Indice") -> << Volver al Indice

Sheet F-4 Laborales
A1: << Volver al Índice
G3: Entidad XXXXXXX | S3: F-4
G4: Revisoría Fiscal
G5: Del 01 de Enero al 31 de Diciembre de 2024 | R5: Auditor
G6: Cifras expresadas en [MONEDA] | R6: Fecha Elaboración
R7: Supervisor
R8: Fecha Aprobación
A10: CALCULADORA AUTOMATIZADA DE PRESTACIONES LABORALES
A11: Revisoría Fiscal - Colombia | Conforme al Código Sustantivo del Trabajo
A13: EMPRESA: | B13: [Nombre de la empresa] | F13: NIT: | G13: [NIT] | J13: PERÍODO: | K13: 2024 | M13: FECHA CÁLCULO: | N13: 12/11/2025
A16: No. | B16: EMPLEADO | C16: IDENTIFICACIÓN | D16: FECHA INGRESO | E16: SALARIO BÁSICO | F16: AUX. TRANSPORTE | G16: OTROS | H16: SALARIO BASE | I16: DÍAS TRABAJADOS | J16: CESANTÍAS | K16: INT. CESANTÍAS | L16: PRIMA SERVICIOS | M16: VACACIONES | N16: TOTAL PRESTACIONES | O16: DIFERENCIA | P16: ESTADO | Q16: OBS.
A17: 1 | E17: 100 | F17: =IF(E17<=([1]PARÁMETROS!$B$4*2),[1]PARÁMETROS!$B$5,0) -> 162000 | H17: =E17+F17+G17 -> 162100 | I17: 5 | J17: =IF(H17="","",H17*I17/[1]PARÁMETROS!$B$10) -> 2251.3889 | K17: =IF(J17="","",J17*[1]PARÁMETROS!$B$7) -> 270.16667 | L17: =IF(H17="","",H17*I17/[1]PARÁMETROS!$B$10) -> 2251.3889 | M17: =IF(E17="","",E17*I17/720) -> 0.69444444 | N17: =J17+K17+L17+M17 -> 4773.6389 | P17: =IF(O17="","",IF(ABS(O17)<1000,"✓ OK","⚠ REVISAR"))
A18: 2 | F18: =IF(E18<=([1]PARÁMETROS!$B$4*2),[1]PARÁMETROS!$B$5,0) -> 162000 | H18: =E18+F18+G18 -> 162000 | I18: 8 | J18: =IF(H18="","",H18*I18/[1]PARÁMETROS!$B$10) -> 3600 | K18: =IF(J18="","",J18*[1]PARÁMETROS!$B$7) -> 432 | L18: =IF(H18="","",H18*I18/[1]PARÁMETROS!$B$10) -> 3600 | M18: 5 | N18: =J18+K18+L18+M18 -> 7637 | P18: =IF(O18="","",IF(ABS(O18)<1000,"✓ OK","⚠ REVISAR"))
A19: 3 | F19: =IF(E19<=([1]PARÁMETROS!$B$4*2),[1]PARÁMETROS!$B$5,0) -> 162000 | H19: =E19+F19+G19 -> 162000 | I19: =IF(D19="","",MIN(360,MAX(0,(DATE(2024,12,31)-D19)))) | J19: =IF(H19="","",H19*I19/[1]PARÁMETROS!$B$10) -> #VALUE! | K19: =IF(J19="","",J19*[1]PARÁMETROS!$B$7) -> #VALUE! | L19: =IF(H19="","",H19*I19/[1]PARÁMETROS!$B$10) -> #VALUE! | M19: =IF(E19="","",E19*I19/720) | N19: =J19+K19+L19+M19 -> #VALUE! | P19: =IF(O19="","",IF(ABS(O19)<1000,"✓ OK","⚠ REVISAR"))
A20: 4 | F20: =IF(E20<=([1]PARÁMETROS!$B$4*2),[1]PARÁMETROS!$B$5,0) -> 162000 | H20: =E20+F20+G20 -> 162000 | I20: =IF(D20="","",MIN(360,MAX(0,(DATE(2024,12,31)-D20)))) | J20: =IF(H20="","",H20*I20/[1]PARÁMETROS!$B$10) -> #VALUE! | K20: =IF(J20="","",J20*[1]PARÁMETROS!$B$7) -> #VALUE! | L20: =IF(H20="","",H20*I20/[1]PARÁMETROS!$B$10) -> #VALUE! | M20: =IF(E20="","",E20*I20/720) | N20: =J20+K20+L20+M20 -> #VALUE! | P20: =IF(O20="","",IF(ABS(O20)<1000,"✓ OK","⚠ REVISAR"))
A21: 5 | F21: =IF(E21<=([1]PARÁMETROS!$B$4*2),[1]PARÁMETROS!$B$5,0) -> 162000 | H21: =E21+F21+G21 -> 162000 | I21: =IF(D21="","",MIN(360,MAX(0,(DATE(2024,12,31)-D21)))) | J21: =IF(H21="","",H21*I21/[1]PARÁMETROS!$B$10) -> #VALUE! | K21: =IF(J21="","",J21*[1]PARÁMETROS!$B$7) -> #VALUE! | L21: =IF(H21="","",H21*I21/[1]PARÁMETROS!$B$10) -> #VALUE! | M21: =IF(E21="","",E21*I21/720) | N21: =J21+K21+L21+M21 -> #VALUE! | P21: =IF(O21="","",IF(ABS(O21)<1000,"✓ OK","⚠ REVISAR"))
A22: 6 | F22: =IF(E22<=([1]PARÁMETROS!$B$4*2),[1]PARÁMETROS!$B$5,0) -> 162000 | H22: =E22+F22+G22 -> 162000 | I22: =IF(D22="","",MIN(360,MAX(0,(DATE(2024,12,31)-D22)))) | J22: =IF(H22="","",H22*I22/[1]PARÁMETROS!$B$10) -> #VALUE! | K22: =IF(J22="","",J22*[1]PARÁMETROS!$B$7) -> #VALUE! | L22: =IF(H22="","",H22*I22/[1]PARÁMETROS!$B$10) -> #VALUE! | M22: =IF(E22="","",E22*I22/720) | N22: =J22+K22+L22+M22 -> #VALUE! | P22: =IF(O22="","",IF(ABS(O22)<1000,"✓ OK","⚠ REVISAR"))
A23: 7 | F23: =IF(E23<=([1]PARÁMETROS!$B$4*2),[1]PARÁMETROS!$B$5,0) -> 162000 | H23: =E23+F23+G23 -> 162000 | I23: =IF(D23="","",MIN(360,MAX(0,(DATE(2024,12,31)-D23)))) | J23: =IF(H23="","",H23*I23/[1]PARÁMETROS!$B$10) -> #VALUE! | K23: =IF(J23="","",J23*[1]PARÁMETROS!$B$7) -> #VALUE! | L23: =IF(H23="","",H23*I23/[1]PARÁMETROS!$B$10) -> #VALUE! | M23: =IF(E23="","",E23*I23/720) | N23: =J23+K23+L23+M23 -> #VALUE! | P23: =IF(O23="","",IF(ABS(O23)<1000,"✓ OK","⚠ REVISAR"))
A24: 8 | F24: =IF(E24<=([1]PARÁMETROS!$B$4*2),[1]PARÁMETROS!$B$5,0) -> 162000 | H24: =E24+F24+G24 -> 162000 | I24: =IF(D24="","",MIN(360,MAX(0,(DATE(2024,12,31)-D24)))) | J24: =IF(H24="","",H24*I24/[1]PARÁMETROS!$B$10) -> #VALUE! | K24: =IF(J24="","",J24*[1]PARÁMETROS!$B$7) -> #VALUE! | L24: =IF(H24="","",H24*I24/[1]PARÁMETROS!$B$10) -> #VALUE! | M24: =IF(E24="","",E24*I24/720) | N24: =J24+K24+L24+M24 -> #VALUE! | P24: =IF(O24="","",IF(ABS(O24)<1000,"✓ OK","⚠ REVISAR"))
A25: 9 | F25: =IF(E25<=([1]PARÁMETROS!$B$4*2),[1]PARÁMETROS!$B$5,0) -> 162000 | H25: =E25+F25+G25 -> 162000 | I25: =IF(D25="","",MIN(360,MAX(0,(DATE(2024,12,31)-D25)))) | J25: =IF(H25="","",H25*I25/[1]PARÁMETROS!$B$10) -> #VALUE! | K25: =IF(J25="","",J25*[1]PARÁMETROS!$B$7) -> #VALUE! | L25: =IF(H25="","",H25*I25/[1]PARÁMETROS!$B$10) -> #VALUE! | M25: =IF(E25="","",E25*I25/720) | N25: =J25+K25+L25+M25 -> #VALUE! | P25: =IF(O25="","",IF(ABS(O25)<1000,"✓ OK","⚠ REVISAR"))
A26: 10 | F26: =IF(E26<=([1]PARÁMETROS!$B$4*2),[1]PARÁMETROS!$B$5,0) -> 162000 | H26: =E26+F26+G26 -> 162000 | I26: =IF(D26="","",MIN(360,MAX(0,(DATE(2024,12,31)-D26)))) | J26: =IF(H26="","",H26*I26/[1]PARÁMETROS!$B$10) -> #VALUE! | K26: =IF(J26="","",J26*[1]PARÁMETROS!$B$7) -> #VALUE! | L26: =IF(H26="","",H26*I26/[1]PARÁMETROS!$B$10) -> #VALUE! | M26: =IF(E26="","",E26*I26/720) | N26: =J26+K26+L26+M26 -> #VALUE! | P26: =IF(O26="","",IF(ABS(O26)<1000,"✓ OK","⚠ REVISAR"))
A27: 11 | F27: =IF(E27<=([1]PARÁMETROS!$B$4*2),[1]PARÁMETROS!$B$5,0) -> 162000 | H27: =E27+F27+G27 -> 162000 | I27: =IF(D27="","",MIN(360,MAX(0,(DATE(2024,12,31)-D27)))) | J27: =IF(H27="","",H27*I27/[1]PARÁMETROS!$B$10) -> #VALUE! | K27: =IF(J27="","",J27*[1]PARÁMETROS!$B$7) -> #VALUE! | L27: =IF(H27="","",H27*I27/[1]PARÁMETROS!$B$10) -> #VALUE! | M27: =IF(E27="","",E27*I27/720) | N27: =J27+K27+L27+M27 -> #VALUE! | P27: =IF(O27="","",IF(ABS(O27)<1000,"✓ OK","⚠ REVISAR"))
A28: 12 | F28: =IF(E28<=([1]PARÁMETROS!$B$4*2),[1]PARÁMETROS!$B$5,0) -> 162000 | H28: =E28+F28+G28 -> 162000 | I28: =IF(D28="","",MIN(360,MAX(0,(DATE(2024,12,31)-D28)))) | J28: =IF(H28="","",H28*I28/[1]PARÁMETROS!$B$10) -> #VALUE! | K28: =IF(J28="","",J28*[1]PARÁMETROS!$B$7) -> #VALUE! | L28: =IF(H28="","",H28*I28/[1]PARÁMETROS!$B$10) -> #VALUE! | M28: =IF(E28="","",E28*I28/720) | N28: =J28+K28+L28+M28 -> #VALUE! | P28: =IF(O28="","",IF(ABS(O28)<1000,"✓ OK","⚠ REVISAR"))
A29: 13 | F29: =IF(E29<=([1]PARÁMETROS!$B$4*2),[1]PARÁMETROS!$B$5,0) -> 162000 | H29: =E29+F29+G29 -> 162000 | I29: =IF(D29="","",MIN(360,MAX(0,(DATE(2024,12,31)-D29)))) | J29: =IF(H29="","",H29*I29/[1]PARÁMETROS!$B$10) -> #VALUE! | K29: =IF(J29="","",J29*[1]PARÁMETROS!$B$7) -> #VALUE! | L29: =IF(H29="","",H29*I29/[1]PARÁMETROS!$B$10) -> #VALUE! | M29: =IF(E29="","",E29*I29/720) | N29: =J29+K29+L29+M29 -> #VALUE! | P29: =IF(O29="","",IF(ABS(O29)<1000,"✓ OK","⚠ REVISAR"))
A30: 14 | F30: =IF(E30<=([1]PARÁMETROS!$B$4*2),[1]PARÁMETROS!$B$5,0) -> 162000 | H30: =E30+F30+G30 -> 162000 | I30: =IF(D30="","",MIN(360,MAX(0,(DATE(2024,12,31)-D30)))) | J30: =IF(H30="","",H30*I30/[1]PARÁMETROS!$B$10) -> #VALUE! | K30: =IF(J30="","",J30*[1]PARÁMETROS!$B$7) -> #VALUE! | L30: =IF(H30="","",H30*I30/[1]PARÁMETROS!$B$10) -> #VALUE! | M30: =IF(E30="","",E30*I30/720) | N30: =J30+K30+L30+M30 -> #VALUE! | P30: =IF(O30="","",IF(ABS(O30)<1000,"✓ OK","⚠ REVISAR"))
... A36: 20 | F36: =IF(E36<=([1]PARÁMETROS!$B$4*2),[1]PARÁMETROS!$B$5,0) -> 162000 | H36: =E36+F36+G36 -> 162000 | I36: =IF(D36="","",MIN(360,MAX(0,(DATE(2024,12,31)-D36)))) | J36: =IF(H36="","",H36*I36/[1]PARÁMETROS!$B$10) -> #VALUE! | K36: =IF(J36="","",J36*[1]PARÁMETROS!$B$7) -> #VALUE! | L36: =IF(H36="","",H36*I36/[1]PARÁMETROS!$B$10) -> #VALUE! | M36: =IF(E36="","",E36*I36/720) | N36: =J36+K36+L36+M36 -> #VALUE! | P36: =IF(O36="","",IF(ABS(O36)<1000,"✓ OK","⚠ REVISAR"))
A37: TOTALES | E37: =SUM(E17:E36) -> 100 | F37: =SUM(F17:F36) -> 3240000 | G37: =SUM(G17:G36) -> 0 | H37: =SUM(H17:H36) -> 3240100 | J37: =SUM(J17:J36) -> #VALUE! | K37: =SUM(K17:K36) -> #VALUE! | L37: =SUM(L17:L36) -> #VALUE! | M37: =SUM(M17:M36) -> 5.6944444 | N37: =SUM(N17:N36) -> #VALUE! | O37: =SUM(O17:O36) -> 0
A40: FÓRMULAS APLICADAS
A41: CONCEPTO | B41: FÓRMULA | D41: BASE LEGAL
A42: CESANTÍAS | B42: =(Salario Base * Días Trabajados) / 360 -> #NAME? | D42: Art. 249 CST
A43: INTERESES CESANTÍAS | D43: Art. 99 Ley 50/1990
A44: PRIMA DE SERVICIOS | B44: =(Salario Base * Días Trabajados) / 360 -> #NAME? | D44: Art. 306 CST
A45: VACACIONES | B45: =(Salario Básico * Días Trabajados) / 720 -> #NAME? | D45: Art. 186 CST
A46: AUXILIO TRANSPORTE | D46: Decreto Gobierno
A48: NOTAS IMPORTANTES
A49: 1. Salario Base = Salario Básico + Auxilio de Transporte + Otros (comisiones, bonificaciones)
A50: 2. El Auxilio de Transporte se otorga SOLO si el salario es igual o menor a 2 SMMLV
A51: 3. Las Vacaciones se calculan SOLO sobre el Salario Básico (no incluye aux. transporte)
A52: 4. Los días trabajados se calculan automáticamente desde la fecha de ingreso
A53: 5. Año laboral = 360 días | Mes laboral = 30 días
...

Sheet F-4.1 Prestaciones
A1: << Volver al Índice
G3: Entidad XXXXXXX | U3: F-4.1
G4: Revisoría Fiscal
G5: Del 01 de Enero al 31 de Diciembre de 2024 | T5: Auditor
G6: Cifras expresadas en [MONEDA] | T6: Fecha Elaboración
T7: Supervisor
T8: Fecha Aprobación
A10: CÁLCULO DE PRESTACIONES SOCIALES - REVISORÍA FISCAL
A11: Conforme al Código Sustantivo del Trabajo - Colombia 2024
A13: EMPRESA: | B13: [Nombre Empresa] | G13: NIT: | H13: [NIT] | K13: PERÍODO: | L13: 2024 | M13: FECHA CORTE: | N13: 31/12/2024 | P13: AUDITOR: | Q13: [Nombre]
A16: No. | B16: EMPLEADO | C16: CÉDULA | D16: FECHA INGRESO | E16: SALARIO BÁSICO | F16: AUX. TRANS. | G16: OTROS INGRESOS | H16: SALARIO BASE | I16: DÍAS TRAB. | J16: CESANTÍAS | K16: INT. CESANTÍAS | L16: PRIMA SERVICIOS | M16: VACACIONES | N16: TOTAL PRESTAC. | O16: REGISTRADO CONTA. | P16: DIFERENCIA | Q16: % DIF. | R16: ESTADO | S16: OBS.
A17: 1 | B17: Ana María Rodríguez González | C17: 52123456 | D17: 43480 | E17: 2800000 | F17: =IF(E17="","",IF(E17<=[2]PARÁMETROS!$B$7,[2]PARÁMETROS!$B$6,0)) -> 0 | G17: 0 | H17: =IF(E17="","",E17+F17+G17) -> 2800000 | I17: =IF(D17="","",MIN(360,MAX(0,(DATE(2024,12,31)-D17)))) -> 360 | J17: =IF(H17="","",H17*I17/[2]PARÁMETROS!$B$49) -> #DIV/0! | K17: =IF(J17="","",J17*[2]PARÁMETROS!$B$12) -> #DIV/0! | L17: =IF(H17="","",H17*I17/[2]PARÁMETROS!$B$49) -> #DIV/0! | M17: =IF(E17="","",E17*I17/720) -> 1400000 | N17: =IF(J17="","",J17+K17+L17+M17) -> #DIV/0! | P17: =IF(O17="","",N17-O17) | Q17: =IF(O17=0,"",P17/O17) | R17: =IF(P17="","",IF(ABS(Q17)<0.05,"✓ OK",IF(ABS(Q17)<0.1,"⚠ REVISAR","❌ CRÍTICO")))
A18: 2 | B18: Carlos Andrés Martínez López | C18: 1018765432 | D18: 43900 | E18: 1500000 | F18: =IF(E18="","",IF(E18<=[2]PARÁMETROS!$B$7,[2]PARÁMETROS!$B$6,0)) -> 0 | G18: 0 | H18: =IF(E18="","",E18+F18+G18) -> 1500000 | I18: =IF(D18="","",MIN(360,MAX(0,(DATE(2024,12,31)-D18)))) -> 360 | J18: =IF(H18="","",H18*I18/[2]PARÁMETROS!$B$49) -> #DIV/0! | K18: =IF(J18="","",J18*[2]PARÁMETROS!$B$12) -> #DIV/0! | L18: =IF(H18="","",H18*I18/[2]PARÁMETROS!$B$49) -> #DIV/0! | M18: =IF(E18="","",E18*I18/720) -> 750000 | N18: =IF(J18="","",J18+K18+L18+M18) -> #DIV/0! | P18: =IF(O18="","",N18-O18) | Q18: =IF(O18=0,"",P18/O18) | R18: =IF(P18="","",IF(ABS(Q18)<0.05,"✓ OK",IF(ABS(Q18)<0.1,"⚠ REVISAR","❌ CRÍTICO")))
A19: 3 | B19: María Fernanda Castro Ruiz | C19: 1015234567 | D19: 43301 | E19: 4200000 | F19: =IF(E19="","",IF(E19<=[2]PARÁMETROS!$B$7,[2]PARÁMETROS!$B$6,0)) -> 0 | G19: 0 | H19: =IF(E19="","",E19+F19+G19) -> 4200000 | I19: =IF(D19="","",MIN(360,MAX(0,(DATE(2024,12,31)-D19)))) -> 360 | J19: =IF(H19="","",H19*I19/[2]PARÁMETROS!$B$49) -> #DIV/0! | K19: =IF(J19="","",J19*[2]PARÁMETROS!$B$12) -> #DIV/0! | L19: =IF(H19="","",H19*I19/[2]PARÁMETROS!$B$49) -> #DIV/0! | M19: =IF(E19="","",E19*I19/720) -> 2100000 | N19: =IF(J19="","",J19+K19+L19+M19) -> #DIV/0! | P19: =IF(O19="","",N19-O19) | Q19: =IF(O19=0,"",P19/O19) | R19: =IF(P19="","",IF(ABS(Q19)<0.05,"✓ OK",IF(ABS(Q19)<0.1,"⚠ REVISAR","❌ CRÍTICO")))
A20: 4 | B20: Juan Pablo Hernández Silva | C20: 1012345678 | D20: 44317 | E20: 1800000 | F20: =IF(E20="","",IF(E20<=[2]PARÁMETROS!$B$7,[2]PARÁMETROS!$B$6,0)) -> 0 | G20: 0 | H20: =IF(E20="","",E20+F20+G20) -> 1800000 | I20: =IF(D20="","",MIN(360,MAX(0,(DATE(2024,12,31)-D20)))) -> 360 | J20: =IF(H20="","",H20*I20/[2]PARÁMETROS!$B$49) -> #DIV/0! | K20: =IF(J20="","",J20*[2]PARÁMETROS!$B$12) -> #DIV/0! | L20: =IF(H20="","",H20*I20/[2]PARÁMETROS!$B$49) -> #DIV/0! | M20: =IF(E20="","",E20*I20/720) -> 900000 | N20: =IF(J20="","",J20+K20+L20+M20) -> #DIV/0! | P20: =IF(O20="","",N20-O20) | Q20: =IF(O20=0,"",P20/O20) | R20: =IF(P20="","",IF(ABS(Q20)<0.05,"✓ OK",IF(ABS(Q20)<0.1,"⚠ REVISAR","❌ CRÍTICO")))
A21: 5 | B21: Diana Carolina Gómez Torres | C21: 52987654 | D21: 44819 | E21: 3500000 | F21: =IF(E21="","",IF(E21<=[2]PARÁMETROS!$B$7,[2]PARÁMETROS!$B$6,0)) -> 0 | G21: 0 | H21: =IF(E21="","",E21+F21+G21) -> 3500000 | I21: =IF(D21="","",MIN(360,MAX(0,(DATE(2024,12,31)-D21)))) -> 360 | J21: =IF(H21="","",H21*I21/[2]PARÁMETROS!$B$49) -> #DIV/0! | K21: =IF(J21="","",J21*[2]PARÁMETROS!$B$12) -> #DIV/0! | L21: =IF(H21="","",H21*I21/[2]PARÁMETROS!$B$49) -> #DIV/0! | M21: =IF(E21="","",E21*I21/720) -> 1750000 | N21: =IF(J21="","",J21+K21+L21+M21) -> #DIV/0! | P21: =IF(O21="","",N21-O21) | Q21: =IF(O21=0,"",P21/O21) | R21: =IF(P21="","",IF(ABS(Q21)<0.05,"✓ OK",IF(ABS(Q21)<0.1,"⚠ REVISAR","❌ CRÍTICO")))
A22: 6 | B22: Luis Fernando Pérez Vargas | C22: 1019876543 | D22: 43064 | E22: 5000000 | F22: =IF(E22="","",IF(E22<=[2]PARÁMETROS!$B$7,[2]PARÁMETROS!$B$6,0)) -> 0 | G22: 0 | H22: =IF(E22="","",E22+F22+G22) -> 5000000 | I22: =IF(D22="","",MIN(360,MAX(0,(DATE(2024,12,31)-D22)))) -> 360 | J22: =IF(H22="","",H22*I22/[2]PARÁMETROS!$B$49) -> #DIV/0! | K22: =IF(J22="","",J22*[2]PARÁMETROS!$B$12) -> #DIV/0! | L22: =IF(H22="","",H22*I22/[2]PARÁMETROS!$B$49) -> #DIV/0! | M22: =IF(E22="","",E22*I22/720) -> 2500000 | N22: =IF(J22="","",J22+K22+L22+M22) -> #DIV/0! | P22: =IF(O22="","",N22-O22) | Q22: =IF(O22=0,"",P22/O22) | R22: =IF(P22="","",IF(ABS(Q22)<0.05,"✓ OK",IF(ABS(Q22)<0.1,"⚠ REVISAR","❌ CRÍTICO")))
A23: 7 | B23: Sandra Milena Jiménez Mora | C23: 52456789 | D23: 43875 | E23: 2200000 | F23: =IF(E23="","",IF(E23<=[2]PARÁMETROS!$B$7,[2]PARÁMETROS!$B$6,0)) -> 0 | G23: 0 | H23: =IF(E23="","",E23+F23+G23) -> 2200000 | I23: =IF(D23="","",MIN(360,MAX(0,(DATE(2024,12,31)-D23)))) -> 360 | J23: =IF(H23="","",H23*I23/[2]PARÁMETROS!$B$49) -> #DIV/0! | K23: =IF(J23="","",J23*[2]PARÁMETROS!$B$12) -> #DIV/0! | L23: =IF(H23="","",H23*I23/[2]PARÁMETROS!$B$49) -> #DIV/0! | M23: =IF(E23="","",E23*I23/720) -> 1100000 | N23: =IF(J23="","",J23+K23+L23+M23) -> #DIV/0! | P23: =IF(O23="","",N23-O23) | Q23: =IF(O23=0,"",P23/O23) | R23: =IF(P23="","",IF(ABS(Q23)<0.05,"✓ OK",IF(ABS(Q23)<0.1,"⚠ REVISAR","❌ CRÍTICO")))
A24: 8 | B24: Jorge Enrique Ramírez Cruz | C24: 1013456789 | D24: 43646 | E24: 3800000 | F24: =IF(E24="","",IF(E24<=[2]PARÁMETROS!$B$7,[2]PARÁMETROS!$B$6,0)) -> 0 | G24: 0 | H24: =IF(E24="","",E24+F24+G24) -> 3800000 | I24: =IF(D24="","",MIN(360,MAX(0,(DATE(2024,12,31)-D24)))) -> 360 | J24: =IF(H24="","",H24*I24/[2]PARÁMETROS!$B$49) -> #DIV/0! | K24: =IF(J24="","",J24*[2]PARÁMETROS!$B$12) -> #DIV/0! | L24: =IF(H24="","",H24*I24/[2]PARÁMETROS!$B$49) -> #DIV/0! | M24: =IF(E24="","",E24*I24/720) -> 1900000 | N24: =IF(J24="","",J24+K24+L24+M24) -> #DIV/0! | P24: =IF(O24="","",N24-O24) | Q24: =IF(O24=0,"",P24/O24) | R24: =IF(P24="","",IF(ABS(Q24)<0.05,"✓ OK",IF(ABS(Q24)<0.1,"⚠ REVISAR","❌ CRÍTICO")))
A25: 9 | F25: =IF(E25="","",IF(E25<=[2]PARÁMETROS!$B$7,[2]PARÁMETROS!$B$6,0)) | G25: 0 | H25: =IF(E25="","",E25+F25+G25) | I25: =IF(D25="","",MIN(360,MAX(0,(DATE(2024,12,31)-D25)))) | J25: =IF(H25="","",H25*I25/[2]PARÁMETROS!$B$49) | K25: =IF(J25="","",J25*[2]PARÁMETROS!$B$12) | L25: =IF(H25="","",H25*I25/[2]PARÁMETROS!$B$49) | M25: =IF(E25="","",E25*I25/720) | N25: =IF(J25="","",J25+K25+L25+M25) | P25: =IF(O25="","",N25-O25) | Q25: =IF(O25=0,"",P25/O25) | R25: =IF(P25="","",IF(ABS(Q25)<0.05,"✓ OK",IF(ABS(Q25)<0.1,"⚠ REVISAR","❌ CRÍTICO")))
A26: 10 | F26: =IF(E26="","",IF(E26<=[2]PARÁMETROS!$B$7,[2]PARÁMETROS!$B$6,0)) | G26: 0 | H26: =IF(E26="","",E26+F26+G26) | I26: =IF(D26="","",MIN(360,MAX(0,(DATE(2024,12,31)-D26)))) | J26: =IF(H26="","",H26*I26/[2]PARÁMETROS!$B$49) | K26: =IF(J26="","",J26*[2]PARÁMETROS!$B$12) | L26: =IF(H26="","",H26*I26/[2]PARÁMETROS!$B$49) | M26: =IF(E26="","",E26*I26/720) | N26: =IF(J26="","",J26+K26+L26+M26) | P26: =IF(O26="","",N26-O26) | Q26: =IF(O26=0,"",P26/O26) | R26: =IF(P26="","",IF(ABS(Q26)<0.05,"✓ OK",IF(ABS(Q26)<0.1,"⚠ REVISAR","❌ CRÍTICO")))
A27: 11 | F27: =IF(E27="","",IF(E27<=[2]PARÁMETROS!$B$7,[2]PARÁMETROS!$B$6,0)) | G27: 0 | H27: =IF(E27="","",E27+F27+G27) | I27: =IF(D27="","",MIN(360,MAX(0,(DATE(2024,12,31)-D27)))) | J27: =IF(H27="","",H27*I27/[2]PARÁMETROS!$B$49) | K27: =IF(J27="","",J27*[2]PARÁMETROS!$B$12) | L27: =IF(H27="","",H27*I27/[2]PARÁMETROS!$B$49) | M27: =IF(E27="","",E27*I27/720) | N27: =IF(J27="","",J27+K27+L27+M27) | P27: =IF(O27="","",N27-O27) | Q27: =IF(O27=0,"",P27/O27) | R27: =IF(P27="","",IF(ABS(Q27)<0.05,"✓ OK",IF(ABS(Q27)<0.1,"⚠ REVISAR","❌ CRÍTICO")))
A28: 12 | F28: =IF(E28="","",IF(E28<=[2]PARÁMETROS!$B$7,[2]PARÁMETROS!$B$6,0)) | G28: 0 | H28: =IF(E28="","",E28+F28+G28) | I28: =IF(D28="","",MIN(360,MAX(0,(DATE(2024,12,31)-D28)))) | J28: =IF(H28="","",H28*I28/[2]PARÁMETROS!$B$49) | K28: =IF(J28="","",J28*[2]PARÁMETROS!$B$12) | L28: =IF(H28="","",H28*I28/[2]PARÁMETROS!$B$49) | M28: =IF(E28="","",E28*I28/720) | N28: =IF(J28="","",J28+K28+L28+M28) | P28: =IF(O28="","",N28-O28) | Q28: =IF(O28=0,"",P28/O28) | R28: =IF(P28="","",IF(ABS(Q28)<0.05,"✓ OK",IF(ABS(Q28)<0.1,"⚠ REVISAR","❌ CRÍTICO")))
A29: 13 | F29: =IF(E29="","",IF(E29<=[2]PARÁMETROS!$B$7,[2]PARÁMETROS!$B$6,0)) | G29: 0 | H29: =IF(E29="","",E29+F29+G29) | I29: =IF(D29="","",MIN(360,MAX(0,(DATE(2024,12,31)-D29)))) | J29: =IF(H29="","",H29*I29/[2]PARÁMETROS!$B$49) | K29: =IF(J29="","",J29*[2]PARÁMETROS!$B$12) | L29: =IF(H29="","",H29*I29/[2]PARÁMETROS!$B$49) | M29: =IF(E29="","",E29*I29/720) | N29: =IF(J29="","",J29+K29+L29+M29) | P29: =IF(O29="","",N29-O29) | Q29: =IF(O29=0,"",P29/O29) | R29: =IF(P29="","",IF(ABS(Q29)<0.05,"✓ OK",IF(ABS(Q29)<0.1,"⚠ REVISAR","❌ CRÍTICO")))
A30: 14 | F30: =IF(E30="","",IF(E30<=[2]PARÁMETROS!$B$7,[2]PARÁMETROS!$B$6,0)) | G30: 0 | H30: =IF(E30="","",E30+F30+G30) | I30: =IF(D30="","",MIN(360,MAX(0,(DATE(2024,12,31)-D30)))) | J30: =IF(H30="","",H30*I30/[2]PARÁMETROS!$B$49) | K30: =IF(J30="","",J30*[2]PARÁMETROS!$B$12) | L30: =IF(H30="","",H30*I30/[2]PARÁMETROS!$B$49) | M30: =IF(E30="","",E30*I30/720) | N30: =IF(J30="","",J30+K30+L30+M30) | P30: =IF(O30="","",N30-O30) | Q30: =IF(O30=0,"",P30/O30) | R30: =IF(P30="","",IF(ABS(Q30)<0.05,"✓ OK",IF(ABS(Q30)<0.1,"⚠ REVISAR","❌ CRÍTICO")))
A31: 15 | F31: =IF(E31="","",IF(E31<=[2]PARÁMETROS!$B$7,[2]PARÁMETROS!$B$6,0)) | G31: 0 | H31: =IF(E31="","",E31+F31+G31) | I31: =IF(D31="","",MIN(360,MAX(0,(DATE(2024,12,31)-D31)))) | J31: =IF(H31="","",H31*I31/[2]PARÁMETROS!$B$49) | K31: =IF(J31="","",J31*[2]PARÁMETROS!$B$12) | L31: =IF(H31="","",H31*I31/[2]PARÁMETROS!$B$49) | M31: =IF(E31="","",E31*I31/720) | N31: =IF(J31="","",J31+K31+L31+M31) | P31: =IF(O31="","",N31-O31) | Q31: =IF(O31=0,"",P31/O31) | R31: =IF(P31="","",IF(ABS(Q31)<0.05,"✓ OK",IF(ABS(Q31)<0.1,"⚠ REVISAR","❌ CRÍTICO")))
A32: 16 | F32: =IF(E32="","",IF(E32<=[2]PARÁMETROS!$B$7,[2]PARÁMETROS!$B$6,0)) | G32: 0 | H32: =IF(E32="","",E32+F32+G32) | I32: =IF(D32="","",MIN(360,MAX(0,(DATE(2024,12,31)-D32)))) | J32: =IF(H32="","",H32*I32/[2]PARÁMETROS!$B$49) | K32: =IF(J32="","",J32*[2]PARÁMETROS!$B$12) | L32: =IF(H32="","",H32*I32/[2]PARÁMETROS!$B$49) | M32: =IF(E32="","",E32*I32/720) | N32: =IF(J32="","",J32+K32+L32+M32) | P32: =IF(O32="","",N32-O32) | Q32: =IF(O32=0,"",P32/O32) | R32: =IF(P32="","",IF(ABS(Q32)<0.05,"✓ OK",IF(ABS(Q32)<0.1,"⚠ REVISAR","❌ CRÍTICO")))
A33: 17 | F33: =IF(E33="","",IF(E33<=[2]PARÁMETROS!$B$7,[2]PARÁMETROS!$B$6,0)) | G33: 0 | H33: =IF(E33="","",E33+F33+G33) | I33: =IF(D33="","",MIN(360,MAX(0,(DATE(2024,12,31)-D33)))) | J33: =IF(H33="","",H33*I33/[2]PARÁMETROS!$B$49) | K33: =IF(J33="","",J33*[2]PARÁMETROS!$B$12) | L33: =IF(H33="","",H33*I33/[2]PARÁMETROS!$B$49) | M33: =IF(E33="","",E33*I33/720) | N33: =IF(J33="","",J33+K33+L33+M33) | P33: =IF(O33="","",N33-O33) | Q33: =IF(O33=0,"",P33/O33) | R33: =IF(P33="","",IF(ABS(Q33)<0.05,"✓ OK",IF(ABS(Q33)<0.1,"⚠ REVISAR","❌ CRÍTICO")))
A34: 18 | F34: =IF(E34="","",IF(E34<=[2]PARÁMETROS!$B$7,[2]PARÁMETROS!$B$6,0)) | G34: 0 | H34: =IF(E34="","",E34+F34+G34) | I34: =IF(D34="","",MIN(360,MAX(0,(DATE(2024,12,31)-D34)))) | J34: =IF(H34="","",H34*I34/[2]PARÁMETROS!$B$49) | K34: =IF(J34="","",J34*[2]PARÁMETROS!$B$12) | L34: =IF(H34="","",H34*I34/[2]PARÁMETROS!$B$49) | M34: =IF(E34="","",E34*I34/720) | N34: =IF(J34="","",J34+K34+L34+M34) | P34: =IF(O34="","",N34-O34) | Q34: =IF(O34=0,"",P34/O34) | R34: =IF(P34="","",IF(ABS(Q34)<0.05,"✓ OK",IF(ABS(Q34)<0.1,"⚠ REVISAR","❌ CRÍTICO")))
A35: 19 | F35: =IF(E35="","",IF(E35<=[2]PARÁMETROS!$B$7,[2]PARÁMETROS!$B$6,0)) | G35: 0 | H35: =IF(E35="","",E35+F35+G35) | I35: =IF(D35="","",MIN(360,MAX(0,(DATE(2024,12,31)-D35)))) | J35: =IF(H35="","",H35*I35/[2]PARÁMETROS!$B$49) | K35: =IF(J35="","",J35*[2]PARÁMETROS!$B$12) | L35: =IF(H35="","",H35*I35/[2]PARÁMETROS!$B$49) | M35: =IF(E35="","",E35*I35/720) | N35: =IF(J35="","",J35+K35+L35+M35) | P35: =IF(O35="","",N35-O35) | Q35: =IF(O35=0,"",P35/O35) | R35: =IF(P35="","",IF(ABS(Q35)<0.05,"✓ OK",IF(ABS(Q35)<0.1,"⚠ REVISAR","❌ CRÍTICO")))
A36: 20 | F36: =IF(E36="","",IF(E36<=[2]PARÁMETROS!$B$7,[2]PARÁMETROS!$B$6,0)) | G36: 0 | H36: =IF(E36="","",E36+F36+G36) | I36: =IF(D36="","",MIN(360,MAX(0,(DATE(2024,12,31)-D36)))) | J36: =IF(H36="","",H36*I36/[2]PARÁMETROS!$B$49) | K36: =IF(J36="","",J36*[2]PARÁMETROS!$B$12) | L36: =IF(H36="","",H36*I36/[2]PARÁMETROS!$B$49) | M36: =IF(E36="","",E36*I36/720) | N36: =IF(J36="","",J36+K36+L36+M36) | P36: =IF(O36="","",N36-O36) | Q36: =IF(O36=0,"",P36/O36) | R36: =IF(P36="","",IF(ABS(Q36)<0.05,"✓ OK",IF(ABS(Q36)<0.1,"⚠ REVISAR","❌ CRÍTICO")))
... A41: 25 | F41: =IF(E41="","",IF(E41<=[2]PARÁMETROS!$B$7,[2]PARÁMETROS!$B$6,0)) | G41: 0 | H41: =IF(E41="","",E41+F41+G41) | I41: =IF(D41="","",MIN(360,MAX(0,(DATE(2024,12,31)-D41)))) | J41: =IF(H41="","",H41*I41/[2]PARÁMETROS!$B$49) | K41: =IF(J41="","",J41*[2]PARÁMETROS!$B$12) | L41: =IF(H41="","",H41*I41/[2]PARÁMETROS!$B$49) | M41: =IF(E41="","",E41*I41/720) | N41: =IF(J41="","",J41+K41+L41+M41) | P41: =IF(O41="","",N41-O41) | Q41: =IF(O41=0,"",P41/O41) | R41: =IF(P41="","",IF(ABS(Q41)<0.05,"✓ OK",IF(ABS(Q41)<0.1,"⚠ REVISAR","❌ CRÍTICO")))
A42: TOTALES | E42: =SUBTOTAL(9,E17:E41) -> 24800000 | F42: =SUBTOTAL(9,F17:F41) -> 0 | G42: =SUBTOTAL(9,G17:G41) -> 0 | H42: =SUBTOTAL(9,H17:H41) -> 24800000 | J42: =SUBTOTAL(9,J17:J41) -> #DIV/0! | K42: =SUBTOTAL(9,K17:K41) -> #DIV/0! | L42: =SUBTOTAL(9,L17:L41) -> #DIV/0! | M42: =SUBTOTAL(9,M17:M41) -> 12400000 | N42: =SUBTOTAL(9,N17:N41) -> #DIV/0! | O42: =SUBTOTAL(9,O17:O41) -> 0 | P42: =SUBTOTAL(9,P17:P41) -> 0
A55: Preparado por: Firma | J55: Revisado por:
A56: Nombre | J56: Nombre
A71: =HYPERLINK("#'INDICE'!A67","<< Volver al Indice") -> << Volver al Indice

Sheet CALCULOS NOMINA
A1: << Volver al Índice
E5: Entidad XXXXXXX | N5: F-4.2
E6: Revisoría Fiscal
E7: Del 01 de Enero al 31 de Diciembre de 2024 | M7: Auditor
E8: Cifras expresadas en [MONEDA] | M8: Fecha Elaboración
M9: Supervisor
A10: F-4.2: CÁLCULO DE NÓMINA | M10: Fecha Aprobación
A12: Empleado | B12: Salario Base | C12: H. Extras | D12: Comisiones | E12: Total Devengado | F12: Salud | G12: Pensión | H12: Otros Desc. | I12: Total Deduc. | J12: Neto Pagar | K12: Pagado | L12: ✓
E13: 100 | F13: =E13*0.04 -> 4 | G13: =E13*0.04 -> 4 | I13: =F13+G13+H13 -> 8 | J13: =E13-I13 -> 92
E14: =B14+C14+D14 -> 0 | F14: =E14*0.04 -> 0 | G14: =E14*0.04 -> 0 | I14: =F14+G14+H14 -> 0 | J14: =E14-I14 -> 0
E15: =B15+C15+D15 -> 0 | F15: =E15*0.04 -> 0 | G15: =E15*0.04 -> 0 | I15: =F15+G15+H15 -> 0 | J15: =E15-I15 -> 0
E16: =B16+C16+D16 -> 0 | F16: =E16*0.04 -> 0 | G16: =E16*0.04 -> 0 | I16: =F16+G16+H16 -> 0 | J16: =E16-I16 -> 0
E17: =B17+C17+D17 -> 0 | F17: =E17*0.04 -> 0 | G17: =E17*0.04 -> 0 | I17: =F17+G17+H17 -> 0 | J17: =E17-I17 -> 0
E18: =B18+C18+D18 -> 0 | F18: =E18*0.04 -> 0 | G18: =E18*0.04 -> 0 | I18: =F18+G18+H18 -> 0 | J18: =E18-I18 -> 0
E19: =B19+C19+D19 -> 0 | F19: =E19*0.04 -> 0 | G19: =E19*0.04 -> 0 | I19: =F19+G19+H19 -> 0 | J19: =E19-I19 -> 0
E20: =B20+C20+D20 -> 0 | F20: =E20*0.04 -> 0 | G20: =E20*0.04 -> 0 | I20: =F20+G20+H20 -> 0 | J20: =E20-I20 -> 0
E21: =B21+C21+D21 -> 0 | F21: =E21*0.04 -> 0 | G21: =E21*0.04 -> 0 | I21: =F21+G21+H21 -> 0 | J21: =E21-I21 -> 0
E22: =B22+C22+D22 -> 0 | F22: =E22*0.04 -> 0 | G22: =E22*0.04 -> 0 | I22: =F22+G22+H22 -> 0 | J22: =E22-I22 -> 0
E23: =B23+C23+D23 -> 0 | F23: =E23*0.04 -> 0 | G23: =E23*0.04 -> 0 | I23: =F23+G23+H23 -> 0 | J23: =E23-I23 -> 0
E24: =B24+C24+D24 -> 0 | F24: =E24*0.04 -> 0 | G24: =E24*0.04 -> 0 | I24: =F24+G24+H24 -> 0 | J24: =E24-I24 -> 0
E25: =B25+C25+D25 -> 0 | F25: =E25*0.04 -> 0 | G25: =E25*0.04 -> 0 | I25: =F25+G25+H25 -> 0 | J25: =E25-I25 -> 0
... E37: =B37+C37+D37 -> 0 | F37: =E37*0.04 -> 0 | G37: =E37*0.04 -> 0 | I37: =F37+G37+H37 -> 0 | J37: =E37-I37 -> 0
A39: TOTALES | B39: =SUM(B13:B38) -> 0 | C39: =SUM(C13:C38) -> 0 | D39: =SUM(D13:D38) -> 0 | E39: =SUM(E13:E38) -> 100 | F39: =SUM(F13:F38) -> 4 | G39: =SUM(G13:G38) -> 4 | I39: =SUM(I13:I38) -> 8 | J39: =SUM(J13:J38) -> 92 | K39: =SUM(K13:K38) -> 0
A51: Preparado por: Firma | H51: Revisado por:
A52: Nombre | H52: Nombre
A62: =HYPERLINK("#'INDICE'!A66","<< Volver al Indice") -> << Volver al Indice

Sheet F-4.3 Parafiscales
A1: << Volver al Índice
E3: Entidad XXXXXXX | N3: F-4.3
E4: Revisoría Fiscal
E5: Del 01 de Enero al 31 de Diciembre de 2024 | M5: Auditor
E6: Cifras expresadas en [MONEDA] | M6: Fecha Elaboración
M7: Supervisor
A8: Aportes parafiscales y seguridad social | M8: Fecha Aprobación
A10: Período | B10: Base Aportes | C10: Salud 8.5% | D10: Pensión 12% | E10: ARL | F10: SENA 2% | G10: ICBF 3% | H10: Caja Comp. 4% | I10: Total | J10: Pagado | K10: Saldo
B11: 100 | C11: =B11*0.085 -> 8.5 | D11: =B11*0.12 -> 12 | F11: =B11*0.02 -> 2 | G11: =B11*0.03 -> 3 | H11: =B11*0.04 -> 4 | I11: =SUM(C11:H11) -> 29.5 | K11: =I11-J11 -> 29.5
C12: =B12*0.085 -> 0 | D12: =B12*0.12 -> 0 | F12: =B12*0.02 -> 0 | G12: =B12*0.03 -> 0 | H12: =B12*0.04 -> 0 | I12: =SUM(C12:H12) -> 0 | K12: =I12-J12 -> 0
C13: =B13*0.085 -> 0 | D13: =B13*0.12 -> 0 | F13: =B13*0.02 -> 0 | G13: =B13*0.03 -> 0 | H13: =B13*0.04 -> 0 | I13: =SUM(C13:H13) -> 0 | K13: =I13-J13 -> 0
C14: =B14*0.085 -> 0 | D14: =B14*0.12 -> 0 | F14: =B14*0.02 -> 0 | G14: =B14*0.03 -> 0 | H14: =B14*0.04 -> 0 | I14: =SUM(C14:H14) -> 0 | K14: =I14-J14 -> 0
C15: =B15*0.085 -> 0 | D15: =B15*0.12 -> 0 | F15: =B15*0.02 -> 0 | G15: =B15*0.03 -> 0 | H15: =B15*0.04 -> 0 | I15: =SUM(C15:H15) -> 0 | K15: =I15-J15 -> 0
C16: =B16*0.085 -> 0 | D16: =B16*0.12 -> 0 | F16: =B16*0.02 -> 0 | G16: =B16*0.03 -> 0 | H16: =B16*0.04 -> 0 | I16: =SUM(C16:H16) -> 0 | K16: =I16-J16 -> 0
C17: =B17*0.085 -> 0 | D17: =B17*0.12 -> 0 | F17: =B17*0.02 -> 0 | G17: =B17*0.03 -> 0 | H17: =B17*0.04 -> 0 | I17: =SUM(C17:H17) -> 0 | K17: =I17-J17 -> 0
C18: =B18*0.085 -> 0 | D18: =B18*0.12 -> 0 | F18: =B18*0.02 -> 0 | G18: =B18*0.03 -> 0 | H18: =B18*0.04 -> 0 | I18: =SUM(C18:H18) -> 0 | K18: =I18-J18 -> 0
C19: =B19*0.085 -> 0 | D19: =B19*0.12 -> 0 | F19: =B19*0.02 -> 0 | G19: =B19*0.03 -> 0 | H19: =B19*0.04 -> 0 | I19: =SUM(C19:H19) -> 0 | K19: =I19-J19 -> 0
C20: =B20*0.085 -> 0 | D20: =B20*0.12 -> 0 | F20: =B20*0.02 -> 0 | G20: =B20*0.03 -> 0 | H20: =B20*0.04 -> 0 | I20: =SUM(C20:H20) -> 0 | K20: =I20-J20 -> 0
C21: =B21*0.085 -> 0 | D21: =B21*0.12 -> 0 | F21: =B21*0.02 -> 0 | G21: =B21*0.03 -> 0 | H21: =B21*0.04 -> 0 | I21: =SUM(C21:H21) -> 0 | K21: =I21-J21 -> 0
C22: =B22*0.085 -> 0 | D22: =B22*0.12 -> 0 | F22: =B22*0.02 -> 0 | G22: =B22*0.03 -> 0 | H22: =B22*0.04 -> 0 | I22: =SUM(C22:H22) -> 0 | K22: =I22-J22 -> 0
A24: TOTALES | B24: =SUM(B11:B23) -> 100 | C24: =SUM(C11:C23) -> 8.5 | D24: =SUM(D11:D23) -> 12 | F24: =SUM(F11:F23) -> 2 | G24: =SUM(G11:G23) -> 3 | H24: =SUM(H11:H23) -> 4 | I24: =SUM(I11:I23) -> 29.5 | J24: =SUM(J11:J23) -> 0 | K24: =SUM(K11:K23) -> 29.5
A38: Preparado por: Firma | K38: Revisado por:
A39: Nombre | K39: Nombre
A49: =HYPERLINK("#'INDICE'!A66","<< Volver al Indice") -> << Volver al Indice

Sheet F-5 Provisiones
A1: << Volver al Índice
F3: Entidad XXXXXXX | N3: F-5
F4: Revisoría Fiscal
F5: Del 01 de Enero al 31 de Diciembre de 2024 | M5: Auditor
F6: Cifras expresadas en [MONEDA] | M6: Fecha Elaboración
M7: Supervisor
M8: Fecha Aprobación
A10: F-5: PASIVOS ESTIMADOS Y PROVISIONES
A11: Objetivo: Verificar cumplimiento NIC 37 / Sección 21 NIIF PYMES
A13: Concepto | B13: Saldo Inicial | C13: Provisión Período | D13: Utilizado | E13: Reversión | F13: Saldo Final | G13: Prob. % | H13: Razonable | I13: Cumple NIC 37 | J13: Soporte | K13: ✓
A14: Garantías productos | F14: =B14+C14-D14-E14 -> 0 | H14: =IF(G14>=0.5,"SÍ","NO") -> NO | I14: =IF(AND(G14>=0.5,F14>0),"SÍ","NO") -> NO
A15: Litigios legales | F15: =B15+C15-D15-E15 -> 0 | H15: =IF(G15>=0.5,"SÍ","NO") -> NO | I15: =IF(AND(G15>=0.5,F15>0),"SÍ","NO") -> NO
A16: Reestructuración | F16: =B16+C16-D16-E16 -> 0 | H16: =IF(G16>=0.5,"SÍ","NO") -> NO | I16: =IF(AND(G16>=0.5,F16>0),"SÍ","NO") -> NO
A17: Desmantelamiento | F17: =B17+C17-D17-E17 -> 0 | H17: =IF(G17>=0.5,"SÍ","NO") -> NO | I17: =IF(AND(G17>=0.5,F17>0),"SÍ","NO") -> NO
A18: Restauración ambiental | F18: =B18+C18-D18-E18 -> 0 | H18: =IF(G18>=0.5,"SÍ","NO") -> NO | I18: =IF(AND(G18>=0.5,F18>0),"SÍ","NO") -> NO
A19: Otros | F19: =B19+C19-D19-E19 -> 0 | H19: =IF(G19>=0.5,"SÍ","NO") -> NO | I19: =IF(AND(G19>=0.5,F19>0),"SÍ","NO") -> NO
A21: TOTAL | B21: =SUM(B14:B20) -> 0 | C21: =SUM(C14:C20) -> 0 | D21: =SUM(D14:D20) -> 0 | E21: =SUM(E14:E20) -> 0 | F21: =SUM(F14:F20) -> 0
A35: Preparado por: Firma | H35: Revisado por:
A36: Nombre | H36: Nombre
A46: =HYPERLINK("#'INDICE'!A66","<< Volver al Indice") -> << Volver al Indice

Sheet F-6 Contingencias
A1: << Volver al Índice
E4: Entidad XXXXXXX | N4: F-6
E5: Revisoría Fiscal
E6: Del 01 de Enero al 31 de Diciembre de 2024 | M6: Auditor
E7: Cifras expresadas en [MONEDA] | M7: Fecha Elaboración
M8: Supervisor
M9: Fecha Aprobación
A11: F-6: CONTINGENCIAS Y PASIVOS EVENTUALES
A13: Descripción | B13: Tipo | C13: Monto Estimado | D13: Probabilidad | E13: Provisionado | F13: Revelado Notas | G13: Estado Actual | H13: Fecha Origen | I13: Abogado/Asesor | J13: Última Actualiz. | K13: Observaciones
A35: Preparado por: Firma | H35: Revisado por:
A36: Nombre | H36: Nombre
A46: =HYPERLINK("#'INDICE'!A71","<< Volver al Indice") -> << Volver al Indice

Sheet F-7 Impuestos
A1: << Volver al Índice
E4: Entidad XXXXXXX | L4: F-7
E5: Revisoría Fiscal
E6: Del 01 de Enero al 31 de Diciembre de 2024 | K6: Auditor
E7: Cifras expresadas en [MONEDA] | K7: Fecha Elaboración
K8: Supervisor
K9: Fecha Aprobación
A11: CÁLCULO IMPUESTO DE RENTA Y COMPLEMENTARIOS
A12: Revisoría Fiscal - Colombia 2024
A14: EMPRESA: | B14: [Razón Social] | F14: NIT: | G14: [NIT] | H14: AÑO GRAVABLE: | I14: 2024
A17: IMPUESTO DE RENTA Y COMPLEMENTARIOS - 2024
A19: EMPRESA: ABC COMERCIALIZADORA S.A.S. | D19: NIT: 900.123.456-7
A21: CONCEPTO | B21: VALOR | C21: BASE LEGAL
A22: Ingresos Operacionales | B22: 50 | C22: Art. 26 ET
A23: Ingresos No Operacionales | B23: 4 | C23: Art. 27 ET
A24: TOTAL INGRESOS | B24: =B22+B23 -> 54 | C24: Suma
A26: Costos de Ventas | B26: 9000000000 | C26: Art. 59 ET
A27: Gastos Operacionales | B27: 3500000000 | C27: Art. 107 ET
A28: Gastos No Operacionales | B28: 200000000 | C28: Art. 115 ET
A29: TOTAL COSTOS Y GASTOS | B29: =B26+B27+B28 -> 12700000000 | C29: Suma
A31: RENTA LÍQUIDA ORDINARIA | B31: =B24-B29 -> -12699999946 | C31: Base
A33: Menos: Compensaciones | B33: 0 | C33: Art. 147 ET
A34: Renta Presuntiva (3% Patrimonio) | B34: 555 | C34: Art. 188 ET
A35: RENTA LÍQUIDA GRAVABLE | B35: =MAX(B31-B33,B34) -> 555 | C35: Mayor
A37: Tarifa 35% | B37: =B35*0.35 -> 194.25 | C37: Art. 240 ET
A38: Menos: Descuentos Tributarios | B38: 150000000 | C38: Art. 254 ET
A40: IMPUESTO DE RENTA A PAGAR | B40: =B37-B38 -> -1.4999981e+08 | C40: Total
A42: Declarado (para comparar) | B42: 485000000 | C42: Input
A43: DIFERENCIA | B43: =B40-B42 -> -6.3499981e+08 | C43: Diferencia
A48: IMPUESTO AL VALOR AGREGADO (IVA) - 2024
A51: MES | B51: VENTAS GRAV. 19% | C51: IVA GENERADO | D51: COMPRAS GRAVADAS | E51: IVA DESCONTABLE | F51: SALDO A PAGAR | G51: IVA PAGADO | H51: DIFERENCIA | I51: ESTADO
A52: Enero | B52: 1200000000 | C52: =B52*0.19 -> 228000000 | D52: 950000000 | E52: =D52*0.19 -> 180500000 | F52: =C52-E52 -> 47500000 | G52: 220000000 | H52: =F52-G52 -> -172500000 | I52: =IF(ABS(H52)<100000,"✓","⚠") -> ⚠
A53: Febrero | B53: 1350000000 | C53: =B53*0.19 -> 256500000 | D53: 1020000000 | E53: =D53*0.19 -> 193800000 | F53: =C53-E53 -> 62700000 | G53: 245000000 | H53: =F53-G53 -> -182300000 | I53: =IF(ABS(H53)<100000,"✓","⚠") -> ⚠
A54: Marzo | B54: 1400000000 | C54: =B54*0.19 -> 266000000 | D54: 1100000000 | E54: =D54*0.19 -> 209000000 | F54: =C54-E54 -> 57000000 | G54: 255000000 | H54: =F54-G54 -> -198000000 | I54: =IF(ABS(H54)<100000,"✓","⚠") -> ⚠
A55: Abril | B55: 1320000000 | C55: =B55*0.19 -> 250800000 | D55: 1050000000 | E55: =D55*0.19 -> 199500000 | F55: =C55-E55 -> 51300000 | G55: 240000000 | H55: =F55-G55 -> -188700000 | I55: =IF(ABS(H55)<100000,"✓","⚠") -> ⚠
A56: Mayo | B56: 1500000000 | C56: =B56*0.19 -> 285000000 | D56: 1150000000 | E56: =D56*0.19 -> 218500000 | F56: =C56-E56 -> 66500000 | G56: 265000000 | H56: =F56-G56 -> -198500000 | I56: =IF(ABS(H56)<100000,"✓","⚠") -> ⚠
A57: Junio | B57: 1450000000 | C57: =B57*0.19 -> 275500000 | D57: 1100000000 | E57: =D57*0.19 -> 209000000 | F57: =C57-E57 -> 66500000 | G57: 260000000 | H57: =F57-G57 -> -193500000 | I57: =IF(ABS(H57)<100000,"✓","⚠") -> ⚠
A58: Julio | B58: 1380000000 | C58: =B58*0.19 -> 262200000 | D58: 1080000000 | E58: =D58*0.19 -> 205200000 | F58: =C58-E58 -> 57000000 | G58: 248000000 | H58: =F58-G58 -> -191000000 | I58: =IF(ABS(H58)<100000,"✓","⚠") -> ⚠
A59: Agosto | B59: 1420000000 | C59: =B59*0.19 -> 269800000 | D59: 1120000000 | E59: =D59*0.19 -> 212800000 | F59: =C59-E59 -> 57000000 | G59: 252000000 | H59: =F59-G59 -> -195000000 | I59: =IF(ABS(H59)<100000,"✓","⚠") -> ⚠
A60: Septiembre | B60: 1460000000 | C60: =B60*0.19 -> 277400000 | D60: 1130000000 | E60: =D60*0.19 -> 214700000 | F60: =C60-E60 -> 62700000 | G60: 258000000 | H60: =F60-G60 -> -195300000 | I60: =IF(ABS(H60)<100000,"✓","⚠") -> ⚠
...
